Workbook
Name DETENIDO: Hoja1!$Y:$Y
Name CONTRAVENTOR: Hoja1!$X:$X
Name TIPIFICACION: Hoja1!$K:$K

Sheet Hoja1
A1: FECHA | B1: HORA | C1: FRANJA HORARIA | D1: JEFE DE SERVICIO | E1: OFICIAL | F1: GRUPO | G1: OPERADOR | H1: GAP | I1: SAE | J1: UBICACIÓN | K1: TIPIFICACIÓN | L1: SUBTIPIFICACION | M1: TIPO EVENTO | N1: CAMARA | O1: BARRIO | P1: INICIO | Q1: FIN | R1: PC | S1: SAME | T1: BOMBEROS | U1: OTROS | V1: HORARIO | W1: RESEÑA | X1: CONTRAVENTORES | Y1: DETENIDOS | Z1: PERS. TRASLADADA | AA1: COMUNA | AB1: OBSERVACIONES | AC1: ORIGEN | AD1: SISEP/ANILLO | AE1: COMENTARIO | AF1: TIPO DE CIERRE | AG1: ERRORES DE CIERRE | AH1: OTROS ERRORES | AI1: OTRAS IMPUTACIONES | AJ1: ACLARACIONES | AK1: GAP | AL1: LP/DNI | AM1: imp | AN1: corr
A2: 45992 | B2: =IF(AND(VALUE(P2)>=VALUE("06:00"),VALUE(P2)<=VALUE("17:59")),"06 A 18","18 A 06") -> 18 A 06 | C2: =IF(AND(VALUE(P2)>=VALUE("00:00"),VALUE(P2)<=VALUE("01:59")),"00:00 a 02:00",IF(AND(VALUE(P2)>=VALUE("02:00"),VALUE(P2)<=VALUE("03:59")),"02:00 a 04:00",IF(AND(VALUE(P2)>=VALUE("04:00"),VALUE(P2)<=VALUE("05:59")),"04:00 a 06:00",IF(AND(VALUE(P2)>=VALUE("06:00"),VALUE(P2)<=VALUE("07:59")),"06:00 a 08:00",IF(AND(VALUE(P2)>=VALUE("08:00"),VALUE(P2)<=VALUE("09:59")),"08:00 a 10:00",IF(AND(VALUE(P2)>=VALUE("10:00"),VALUE(P2)<=VALUE("11:59")),"10:00 a 12:00",IF(AND(VALUE(P2)>=VALUE("12:00"),VALUE(P2)<=VALUE("13:59")),"12:00 a 14:00",IF(AND(VALUE(P2)>=VALUE("14:00"),VALUE(P2)<=VALUE("15:59")),"14:00 a 16:00",IF(AND(VALUE(P2)>=VALUE("16:00"),VALUE(P2)<=VALUE("17:59")),"16:00 a 18:00",IF(AND(VALUE(P2)>=VALUE("18:00"),VALUE(P2)<=VALUE("19:59")),"18:00 a 20:00",IF(AND(VALUE(P2)>=VALUE("20:00"),VALUE(P2)<=VALUE("21:59")),"20:00 a 22:00",IF(AND(VALUE(P2)>=VALUE("22:00"),VALUE(P2)<=VALUE("23:59")),"22:00 a 00:00","no corresponde")))))))))))) -> 00:00 a 02:00 | D2: ARGUELLO | E2: QUINTANA, GILDA | F2: 3 | G2: VILLANUEVA, CELESTE | H2: 919892 | I2: 46736933 | J2: CHACARITA | K2: COLABORACION | L2: ROBO/HURTO | N2: PALERMO O203 | O2: Palermo | P2: 0.014583333 | Q2: 0.035416667 | R2: 0.014583333 | S2: - | T2: - | U2: - | V2: - | W2: SE TOMA CONOCIMIENTO POR MEDIO DE LA CARTA SAE N° 46736933 DENUNCIANTE REFIERE QUE LE HABRIAN SUSTRAIDO LA BICICLETA. SIENDO LAS 00:21 HS. SE OBSERVA POR LA CAMARA PALERMOO203 EMPLAZADA EN MEDRANO 1038 Y CORDOBA DONDE SE VISUALIZA AL PERSONAL POLICIAL ENTREVISTANDO A UNA FEMENINA Y A UN MASCULINO. 00:51 HS. SE RETIRA EL MOVIL POLICIAL DANDO ASI POR FINALIZADO EL EVENTO. POSTERIORMENTE SE TOMA CONOCIMIENTO POR MEDIO DE LA AMPLIACION DE LA CARTA SAE QUE MOVIL 914 INFORMA QUE SE REALIZA CONSULTA CON LA FISCALIA NACIONAL CRIMINAL Y CORRECCIONAL N°29 A CARGO DEL DR. LUCIO HERRERA SECRETARIA UNICA A CARGO DE LA DRA. GONZALEZ DISPONE ACTUACIONES POR HURTO. | X2: 0 | Y2: 0 | Z2: 0 | AA2: 14B | AB2: U | AC2: CARTA | AF2: CARTA FINALIZADA | AL2: =VLOOKUP(G2,Hoja2!P:Q,2,0) -> 45324330 | AM2: =IF(OR(Y2>0,X2>0),"IMPUTADO","NADA") -> NADA | AN2: =IF(AND(AM2="IMPUTADO",ISBLANK(M2)),"FALTO","NO") -> NO
A3: 45992 | B3: =IF(AND(VALUE(P3)>=VALUE("06:00"),VALUE(P3)<=VALUE("17:59")),"06 A 18","18 A 06") -> 18 A 06 | C3: =IF(AND(VALUE(P3)>=VALUE("00:00"),VALUE(P3)<=VALUE("01:59")),"00:00 a 02:00",IF(AND(VALUE(P3)>=VALUE("02:00"),VALUE(P3)<=VALUE("03:59")),"02:00 a 04:00",IF(AND(VALUE(P3)>=VALUE("04:00"),VALUE(P3)<=VALUE("05:59")),"04:00 a 06:00",IF(AND(VALUE(P3)>=VALUE("06:00"),VALUE(P3)<=VALUE("07:59")),"06:00 a 08:00",IF(AND(VALUE(P3)>=VALUE("08:00"),VALUE(P3)<=VALUE("09:59")),"08:00 a 10:00",IF(AND(VALUE(P3)>=VALUE("10:00"),VALUE(P3)<=VALUE("11:59")),"10:00 a 12:00",IF(AND(VALUE(P3)>=VALUE("12:00"),VALUE(P3)<=VALUE("13:59")),"12:00 a 14:00",IF(AND(VALUE(P3)>=VALUE("14:00"),VALUE(P3)<=VALUE("15:59")),"14:00 a 16:00",IF(AND(VALUE(P3)>=VALUE("16:00"),VALUE(P3)<=VALUE("17:59")),"16:00 a 18:00",IF(AND(VALUE(P3)>=VALUE("18:00"),VALUE(P3)<=VALUE("19:59")),"18:00 a 20:00",IF(AND(VALUE(P3)>=VALUE("20:00"),VALUE(P3)<=VALUE("21:59")),"20:00 a 22:00",IF(AND(VALUE(P3)>=VALUE("22:00"),VALUE(P3)<=VALUE("23:59")),"22:00 a 00:00","no corresponde")))))))))))) -> 00:00 a 02:00 | D3: ARGUELLO | E3: QUINTANA, GILDA | F3: 3 | G3: LOBOS, LUCRECIA | H3: 919856 | I3: 46736945 | J3: CHACARITA | K3: PERSONA CAIDA | N3: BALVANERA28 | O3: Balvanera | P3: 0.010416667 | Q3: 0.020833333 | R3: 0.025694444 | S3: - | T3: - | U3: - | V3: - | W3: SE TOMA CONOCIMIENTO MEDIANTE CARTA SAE SOBRE DENUNCIANTE QUIEN REFIERE QUE MASCULINO TAXISTA ESTARIA APARENTEMENTE EBRIO DENTRO DEL VEHICULO ESTACIONADO EN EL LUGAR. SE VISUALIZA VEHICULO DE ALQUILER EN EL LUGAR. ARRIBA PERSONAL POLICIAL DANDO CON EL RODADO EN MENCION. SE INFORMA SE TRATA DE MASCULINO DORMITANDO EN SU VEHICULO PARTICULAR.- | X3: 0 | Y3: 0 | Z3: 0 | AA3: 3A | AB3: U | AC3: CARTA | AD3: SISEP | AF3: CARTA FINALIZADA | AL3: =VLOOKUP(G3,Hoja2!P:Q,2,0) -> 28898771 | AM3: =IF(OR(Y3>0,X3>0),"IMPUTADO","NADA") -> NADA | AN3: =IF(AND(AM3="IMPUTADO",ISBLANK(M3)),"FALTO","NO") -> NO
A4: 45992 | B4: =IF(AND(VALUE(P4)>=VALUE("06:00"),VALUE(P4)<=VALUE("17:59")),"06 A 18","18 A 06") -> 18 A 06 | C4: =IF(AND(VALUE(P4)>=VALUE("00:00"),VALUE(P4)<=VALUE("01:59")),"00:00 a 02:00",IF(AND(VALUE(P4)>=VALUE("02:00"),VALUE(P4)<=VALUE("03:59")),"02:00 a 04:00",IF(AND(VALUE(P4)>=VALUE("04:00"),VALUE(P4)<=VALUE("05:59")),"04:00 a 06:00",IF(AND(VALUE(P4)>=VALUE("06:00"),VALUE(P4)<=VALUE("07:59")),"06:00 a 08:00",IF(AND(VALUE(P4)>=VALUE("08:00"),VALUE(P4)<=VALUE("09:59")),"08:00 a 10:00",IF(AND(VALUE(P4)>=VALUE("10:00"),VALUE(P4)<=VALUE("11:59")),"10:00 a 12:00",IF(AND(VALUE(P4)>=VALUE("12:00"),VALUE(P4)<=VALUE("13:59")),"12:00 a 14:00",IF(AND(VALUE(P4)>=VALUE("14:00"),VALUE(P4)<=VALUE("15:59")),"14:00 a 16:00",IF(AND(VALUE(P4)>=VALUE("16:00"),VALUE(P4)<=VALUE("17:59")),"16:00 a 18:00",IF(AND(VALUE(P4)>=VALUE("18:00"),VALUE(P4)<=VALUE("19:59")),"18:00 a 20:00",IF(AND(VALUE(P4)>=VALUE("20:00"),VALUE(P4)<=VALUE("21:59")),"20:00 a 22:00",IF(AND(VALUE(P4)>=VALUE("22:00"),VALUE(P4)<=VALUE("23:59")),"22:00 a 00:00","no corresponde")))))))))))) -> 00:00 a 02:00 | D4: ARGUELLO | E4: QUINTANA, GILDA | F4: 3 | G4: RIGONI, VALENTINA | H4: 919879 | I4: 46737131 | J4: CHACARITA | K4: PERSONA CAIDA | N4: FLORESTA16CAM02 | O4: Floresta | P4: 0.034722222 | Q4: 0.059722222 | R4: 0.034722222 | S4: 0.048611111 | T4: - | U4: - | V4: - | W4: SE TOMA CONOCIMIENTO MEDIANTE CARTA SAE N°46737131 QUE DENUNCIANTE REFIERE QUE UNA MUJER SE CAYÓ DE LA MOTO. ESTA LASTIMADA Y SANGRANDO DE LA BOCA. SIENDO LAS 00:50HS. SE TOMA CÁMARA FLORESTA16CAM02 EMPLAZADA EN RIVADAVIA 7902 Y AZUL DONDE SE VISUALIZA A UNA PERSONA TENDIDA EN EL MEDIO DE LA CINTA ASFÁLTICA SIENDO ASISTIDA POR TRANSEÚNTES. SE PROCEDE A REALIZAR LÍNEA DE TIEMPO SOBRE LA MISMA CÁMARA DONDE SIENDO LAS 00:47HS. SE VISUALIZA A UN MOTOVEHICULO CIRCULANDO POR CALLE RIVADAVIA SENTIDO AZUL DONDE ESTE PIERDE EL CONTROL DEL MOTOVEHICULO Y CAE SOBRE CINTA ASFÁLTICA. 01:03HS. ARRIBA PERSONAL POLICIAL AL LUGAR. 01:10HS. ARRIBA SAME. 01:21HS. SE RETIRA SAME CON TRASLADO. 01:26HS. SE RETIRA PERSONAL POLICIAL DANDO ASÍ COMO FINALIZADO ESTE EVENTO. POSTERIORMENTE SE AMPLÍA MEDIANTE CARTA SAE QUE SECTOR 1 INFORMA ARRIBO SAME 404 DEL HOSPITAL PIÑEIRO A CARGO DE DRA. DE LA GARCÍA MATRICULA N° 198166 QUIEN ASISTE Y DERIVA CON DIAGNOSTICO POLITRAUMATISMO A MISMO NOSOCOMIO. | X4: 0 | Y4: 0 | Z4: 1 | AA4: 10C | AB4: U | AC4: CARTA | AD4: SISEP | AE4: 1 TRASLADO SAME | AF4: CARTA FINALIZADA | AL4: =VLOOKUP(G4,Hoja2!P:Q,2,0) -> 45756657 | AM4: =IF(OR(Y4>0,X4>0),"IMPUTADO","NADA") -> NADA | AN4: =IF(AND(AM4="IMPUTADO",ISBLANK(M4)),"FALTO","NO") -> NO
A5: 45992 | B5: =IF(AND(VALUE(P5)>=VALUE("06:00"),VALUE(P5)<=VALUE("17:59")),"06 A 18","18 A 06") -> 18 A 06 | C5: =IF(AND(VALUE(P5)>=VALUE("00:00"),VALUE(P5)<=VALUE("01:59")),"00:00 a 02:00",IF(AND(VALUE(P5)>=VALUE("02:00"),VALUE(P5)<=VALUE("03:59")),"02:00 a 04:00",IF(AND(VALUE(P5)>=VALUE("04:00"),VALUE(P5)<=VALUE("05:59")),"04:00 a 06:00",IF(AND(VALUE(P5)>=VALUE("06:00"),VALUE(P5)<=VALUE("07:59")),"06:00 a 08:00",IF(AND(VALUE(P5)>=VALUE("08:00"),VALUE(P5)<=VALUE("09:59")),"08:00 a 10:00",IF(AND(VALUE(P5)>=VALUE("10:00"),VALUE(P5)<=VALUE("11:59")),"10:00 a 12:00",IF(AND(VALUE(P5)>=VALUE("12:00"),VALUE(P5)<=VALUE("13:59")),"12:00 a 14:00",IF(AND(VALUE(P5)>=VALUE("14:00"),VALUE(P5)<=VALUE("15:59")),"14:00 a 16:00",IF(AND(VALUE(P5)>=VALUE("16:00"),VALUE(P5)<=VALUE("17:59")),"16:00 a 18:00",IF(AND(VALUE(P5)>=VALUE("18:00"),VALUE(P5)<=VALUE("19:59")),"18:00 a 20:00",IF(AND(VALUE(P5)>=VALUE("20:00"),VALUE(P5)<=VALUE("21:59")),"20:00 a 22:00",IF(AND(VALUE(P5)>=VALUE("22:00"),VALUE(P5)<=VALUE("23:59")),"22:00 a 00:00","no corresponde")))))))))))) -> 00:00 a 02:00 | D5: ARGUELLO | E5: QUINTANA, GILDA | F5: 3 | G5: ALONSO, JORGE ANTONIO | H5: 919860 | I5: 46737148 | J5: CHACARITA | K5: ROBO/HURTO | M5: ROBO/HURTO | N5: FLORES27 | O5: Flores | P5: 0.033333333 | Q5: 0.11111111 | R5: 0.039583333 | S5: - | T5: - | U5: - | V5: - | W5: SE VISUALIZA UN MASCULINO TRANSPORTANDO UNA BATERIA EN INTERIOR DE COLECTIVO LINEA 76 INTERNO 1302 SENTIDO A SAN PEDRITO. ARRIBA PERSONAL POLICIAL INTERCEPTANDO EL COELCTIVO EN CUESTION. SE VERIFICA LINEA DE TIEMPO OBSERVANDO A DOS MACULINOS LEVANTAR EL CAPOT DE UN RODADO Y SUSTRAER LA BATERIA PARA LUEGO ASCENDER A LA UNIDAD DE COLECTIVO. SE INFORMA SE HALLA EL VEHICULO VIOLENTADO CON FALTANTE DE BATERIA. SE LABRAN ACTUASCIONES POR ROBO. DETENCION DE AMBOS MASCULINOS.-- | X5: 0 | Y5: 2 | Z5: 0 | AA5: 7C | AB5: U | AC5: MONITOREO | AD5: SISEP | AE5: 2 DETENIDOS.- | AF5: FINALIZA CON IMPUTADO/S | AL5: =VLOOKUP(G5,Hoja2!P:Q,2,0) -> 23671702 | AM5: =IF(OR(Y5>0,X5>0),"IMPUTADO","NADA") -> IMPUTADO | AN5: =IF(AND(AM5="IMPUTADO",ISBLANK(M5)),"FALTO","NO") -> NO
A6: 45992 | B6: =IF(AND(VALUE(P6)>=VALUE("06:00"),VALUE(P6)<=VALUE("17:59")),"06 A 18","18 A 06") -> 18 A 06 | C6: =IF(AND(VALUE(P6)>=VALUE("00:00"),VALUE(P6)<=VALUE("01:59")),"00:00 a 02:00",IF(AND(VALUE(P6)>=VALUE("02:00"),VALUE(P6)<=VALUE("03:59")),"02:00 a 04:00",IF(AND(VALUE(P6)>=VALUE("04:00"),VALUE(P6)<=VALUE("05:59")),"04:00 a 06:00",IF(AND(VALUE(P6)>=VALUE("06:00"),VALUE(P6)<=VALUE("07:59")),"06:00 a 08:00",IF(AND(VALUE(P6)>=VALUE("08:00"),VALUE(P6)<=VALUE("09:59")),"08:00 a 10:00",IF(AND(VALUE(P6)>=VALUE("10:00"),VALUE(P6)<=VALUE("11:59")),"10:00 a 12:00",IF(AND(VALUE(P6)>=VALUE("12:00"),VALUE(P6)<=VALUE("13:59")),"12:00 a 14:00",IF(AND(VALUE(P6)>=VALUE("14:00"),VALUE(P6)<=VALUE("15:59")),"14:00 a 16:00",IF(AND(VALUE(P6)>=VALUE("16:00"),VALUE(P6)<=VALUE("17:59")),"16:00 a 18:00",IF(AND(VALUE(P6)>=VALUE("18:00"),VALUE(P6)<=VALUE("19:59")),"18:00 a 20:00",IF(AND(VALUE(P6)>=VALUE("20:00"),VALUE(P6)<=VALUE("21:59")),"20:00 a 22:00",IF(AND(VALUE(P6)>=VALUE("22:00"),VALUE(P6)<=VALUE("23:59")),"22:00 a 00:00","no corresponde")))))))))))) -> 00:00 a 02:00 | D6: ARGUELLO | E6: QUINTANA, GILDA | F6: 3 | G6: RIOS MESA, MALCOM MIGUEL | H6: 919876 | I6: 46737165 | J6: CHACARITA | K6: COLABORACION | L6: SUICIDIO/TTVA. SUICIDIO | N6: PALERMO O136 | O6: Palermo | P6: 0.041666667 | Q6: 0.18611111 | R6: 0.041666667 | S6: 0.05 | T6: - | U6: - | V6: - | W6: SE TOMA CONOCIMIENTO MEDIANTE CARTA SAE SOBRE DENUNCIANTE QUIEN REFIERE QUE ESCUCHA UN FEMENINO EN DEMANDA DE AUXILIO. SE VISUALIZA PERSONAL POLICIAL. ARRIBA SAME QUIEN ASISTE EN EL LUGAR Y CONSTATA OBITO. SE INFORMA FEMENINO REFIERE QUE EL MASCULINO HABRIA CONSUMIDO COCAINA Y ASCIENDE AL DORMITORIO, EL MISMOCOMIENZSA A DEMORAR DONDE LA FEMENINO SUBE AL MISMO Y ESTE SE TIRA DEL BARANDAL CON UNA SABANA. CONSTATAN OBITO HORAS 01:27 EN POSICION CUBITO DORSAL. SE LABRAN ACTS POR AVERIGUACION CAUSALES DE MUERTE.- | X6: 0 | Y6: 0 | Z6: 0 | AA6: 14B | AB6: U | AC6: CARTA | AE6: 1 OBITO | AF6: CARTA FINALIZADA | AL6: =VLOOKUP(G6,Hoja2!P:Q,2,0) -> 27382983 | AM6: =IF(OR(Y6>0,X6>0),"IMPUTADO","NADA") -> NADA | AN6: =IF(AND(AM6="IMPUTADO",ISBLANK(M6)),"FALTO","NO") -> NO
A7: 45992 | B7: =IF(AND(VALUE(P7)>=VALUE("06:00"),VALUE(P7)<=VALUE("17:59")),"06 A 18","18 A 06") -> 18 A 06 | C7: =IF(AND(VALUE(P7)>=VALUE("00:00"),VALUE(P7)<=VALUE("01:59")),"00:00 a 02:00",IF(AND(VALUE(P7)>=VALUE("02:00"),VALUE(P7)<=VALUE("03:59")),"02:00 a 04:00",IF(AND(VALUE(P7)>=VALUE("04:00"),VALUE(P7)<=VALUE("05:59")),"04:00 a 06:00",IF(AND(VALUE(P7)>=VALUE("06:00"),VALUE(P7)<=VALUE("07:59")),"06:00 a 08:00",IF(AND(VALUE(P7)>=VALUE("08:00"),VALUE(P7)<=VALUE("09:59")),"08:00 a 10:00",IF(AND(VALUE(P7)>=VALUE("10:00"),VALUE(P7)<=VALUE("11:59")),"10:00 a 12:00",IF(AND(VALUE(P7)>=VALUE("12:00"),VALUE(P7)<=VALUE("13:59")),"12:00 a 14:00",IF(AND(VALUE(P7)>=VALUE("14:00"),VALUE(P7)<=VALUE("15:59")),"14:00 a 16:00",IF(AND(VALUE(P7)>=VALUE("16:00"),VALUE(P7)<=VALUE("17:59")),"16:00 a 18:00",IF(AND(VALUE(P7)>=VALUE("18:00"),VALUE(P7)<=VALUE("19:59")),"18:00 a 20:00",IF(AND(VALUE(P7)>=VALUE("20:00"),VALUE(P7)<=VALUE("21:59")),"20:00 a 22:00",IF(AND(VALUE(P7)>=VALUE("22:00"),VALUE(P7)<=VALUE("23:59")),"22:00 a 00:00","no corresponde")))))))))))) -> 00:00 a 02:00 | D7: ARGUELLO | E7: QUINTANA, GILDA | F7: 3 | G7: RODRIGUEZ BAEZ, MAXIMA | H7: 919857 | I7: 46737219 | J7: CHACARITA | K7: PERSONA CAIDA | N7: AGRONOMIA 01 CAM2 | O7: Agronomia | P7: 0.045833333 | Q7: 0.070138889 | R7: 0.048611111 | S7: 0.055555556 | T7: - | U7: - | V7: - | W7: SE TOMA CONOCIMIENTO MEDIANTE CARTA SAE SOBRE DENUNCIANTE QUIENREFIERE QUE HABRIA UN FEMENINO CAIDO DE LA MOTO ESTARIA GOLPEADA EN EL HOMBRO. SE VISUALIZA MASCULINO CAIDOEN LA VIA PUBLICA. SE VERIFICA LIENA DE TIEM POOBSERVANDO FEMENINO CAER POR MALA MANIOBRA POR INCLEMENCIA CLIMATICA. ARRIBA PERSONAL POLICIAL Y SAME QUIEN ASISTE Y DERIVA CON DIAGN TRAUMATISMO DDEHOMBRO DERECHO. SE LABRA CONSTANCIA EN PARTE.- | X7: 0 | Y7: 0 | Z7: 1 | AA7: 15C | AB7: U | AC7: CARTA | AD7: SISEP | AE7: 1 TRASLADO SAME | AF7: CARTA FINALIZADA | AL7: =VLOOKUP(G7,Hoja2!P:Q,2,0) -> 44544554 | AM7: =IF(OR(Y7>0,X7>0),"IMPUTADO","NADA") -> NADA | AN7: =IF(AND(AM7="IMPUTADO",ISBLANK(M7)),"FALTO","NO") -> NO
A8: 45992 | B8: =IF(AND(VALUE(P8)>=VALUE("06:00"),VALUE(P8)<=VALUE("17:59")),"06 A 18","18 A 06") -> 18 A 06 | C8: =IF(AND(VALUE(P8)>=VALUE("00:00"),VALUE(P8)<=VALUE("01:59")),"00:00 a 02:00",IF(AND(VALUE(P8)>=VALUE("02:00"),VALUE(P8)<=VALUE("03:59")),"02:00 a 04:00",IF(AND(VALUE(P8)>=VALUE("04:00"),VALUE(P8)<=VALUE("05:59")),"04:00 a 06:00",IF(AND(VALUE(P8)>=VALUE("06:00"),VALUE(P8)<=VALUE("07:59")),"06:00 a 08:00",IF(AND(VALUE(P8)>=VALUE("08:00"),VALUE(P8)<=VALUE("09:59")),"08:00 a 10:00",IF(AND(VALUE(P8)>=VALUE("10:00"),VALUE(P8)<=VALUE("11:59")),"10:00 a 12:00",IF(AND(VALUE(P8)>=VALUE("12:00"),VALUE(P8)<=VALUE("13:59")),"12:00 a 14:00",IF(AND(VALUE(P8)>=VALUE("14:00"),VALUE(P8)<=VALUE("15:59")),"14:00 a 16:00",IF(AND(VALUE(P8)>=VALUE("16:00"),VALUE(P8)<=VALUE("17:59")),"16:00 a 18:00",IF(AND(VALUE(P8)>=VALUE("18:00"),VALUE(P8)<=VALUE("19:59")),"18:00 a 20:00",IF(AND(VALUE(P8)>=VALUE("20:00"),VALUE(P8)<=VALUE("21:59")),"20:00 a 22:00",IF(AND(VALUE(P8)>=VALUE("22:00"),VALUE(P8)<=VALUE("23:59")),"22:00 a 00:00","no corresponde")))))))))))) -> 00:00 a 02:00 | D8: ARGUELLO | E8: COLO, NADIA | F8: 3 | G8: PONCE, VANESA PAOLA | H8: 919887 | I8: 46737291 | J8: PUERTO MADERO | K8: INCIDENCIA EN VIA PUBLICA | N8: BARRACAS82 | O8: Barracas | P8: 0.051388889 | Q8: 0.059027778 | R8: 0.054861111 | S8: - | T8: - | U8: - | V8: - | W8: SE VISUALIZA POR CAMARA BARRACAS 82 UNA INCIDENCIA ENTRE DOS MASCULINOS LOS CUALES MINUTOS POSTERIORES SE RETIRAN EN DISTINTAS DIRECCIONES. ARRIBA PERSONAL POLCIAL SIN DAR CON LOS MISMOS. | X8: 0 | Y8: 0 | Z8: 0 | AA8: 4D | AB8: U | AC8: MONITOREO | AF8: CARTA FINALIZADA | AL8: =VLOOKUP(G8,Hoja2!P:Q,2,0) -> 30642469 | AM8: =IF(OR(Y8>0,X8>0),"IMPUTADO","NADA") -> NADA | AN8: =IF(AND(AM8="IMPUTADO",ISBLANK(M8)),"FALTO","NO") -> NO
A9: 45992 | B9: =IF(AND(VALUE(P9)>=VALUE("06:00"),VALUE(P9)<=VALUE("17:59")),"06 A 18","18 A 06") -> 18 A 06 | C9: =IF(AND(VALUE(P9)>=VALUE("00:00"),VALUE(P9)<=VALUE("01:59")),"00:00 a 02:00",IF(AND(VALUE(P9)>=VALUE("02:00"),VALUE(P9)<=VALUE("03:59")),"02:00 a 04:00",IF(AND(VALUE(P9)>=VALUE("04:00"),VALUE(P9)<=VALUE("05:59")),"04:00 a 06:00",IF(AND(VALUE(P9)>=VALUE("06:00"),VALUE(P9)<=VALUE("07:59")),"06:00 a 08:00",IF(AND(VALUE(P9)>=VALUE("08:00"),VALUE(P9)<=VALUE("09:59")),"08:00 a 10:00",IF(AND(VALUE(P9)>=VALUE("10:00"),VALUE(P9)<=VALUE("11:59")),"10:00 a 12:00",IF(AND(VALUE(P9)>=VALUE("12:00"),VALUE(P9)<=VALUE("13:59")),"12:00 a 14:00",IF(AND(VALUE(P9)>=VALUE("14:00"),VALUE(P9)<=VALUE("15:59")),"14:00 a 16:00",IF(AND(VALUE(P9)>=VALUE("16:00"),VALUE(P9)<=VALUE("17:59")),"16:00 a 18:00",IF(AND(VALUE(P9)>=VALUE("18:00"),VALUE(P9)<=VALUE("19:59")),"18:00 a 20:00",IF(AND(VALUE(P9)>=VALUE("20:00"),VALUE(P9)<=VALUE("21:59")),"20:00 a 22:00",IF(AND(VALUE(P9)>=VALUE("22:00"),VALUE(P9)<=VALUE("23:59")),"22:00 a 00:00","no corresponde")))))))))))) -> 00:00 a 02:00 | D9: ARGUELLO | E9: QUINTANA, GILDA | F9: 3 | G9: SOSA, DÉBORA | H9: 919846 | I9: 46737350 | J9: CHACARITA | K9: INCIDENCIA EN VIA PUBLICA | N9: FLORES O137 | O9: Flores | P9: 0.059027778 | Q9: 0.068055556 | R9: 0.061805556 | S9: - | T9: - | U9: - | V9: - | W9: SE VISUALIZA UNA INCIDENCIA EN EL LUGAR.A RRIBA PERSONAL POLICIAL DANDO CON LAS PARTE. SE INFORMA SE TRATO DE INCIDENCIA SOLUCIONADA SIN NOVEDAD.- | X9: 0 | Y9: 0 | Z9: 0 | AA9: 7A | AB9: U | AC9: MONITOREO | AD9: SISEP | AF9: CARTA FINALIZADA | AL9: =VLOOKUP(G9,Hoja2!P:Q,2,0) -> 38862287 | AM9: =IF(OR(Y9>0,X9>0),"IMPUTADO","NADA") -> NADA | AN9: =IF(AND(AM9="IMPUTADO",ISBLANK(M9)),"FALTO","NO") -> NO
A10: 45992 | B10: =IF(AND(VALUE(P10)>=VALUE("06:00"),VALUE(P10)<=VALUE("17:59")),"06 A 18","18 A 06") -> 18 A 06 | C10: =IF(AND(VALUE(P10)>=VALUE("00:00"),VALUE(P10)<=VALUE("01:59")),"00:00 a 02:00",IF(AND(VALUE(P10)>=VALUE("02:00"),VALUE(P10)<=VALUE("03:59")),"02:00 a 04:00",IF(AND(VALUE(P10)>=VALUE("04:00"),VALUE(P10)<=VALUE("05:59")),"04:00 a 06:00",IF(AND(VALUE(P10)>=VALUE("06:00"),VALUE(P10)<=VALUE("07:59")),"06:00 a 08:00",IF(AND(VALUE(P10)>=VALUE("08:00"),VALUE(P10)<=VALUE("09:59")),"08:00 a 10:00",IF(AND(VALUE(P10)>=VALUE("10:00"),VALUE(P10)<=VALUE("11:59")),"10:00 a 12:00",IF(AND(VALUE(P10)>=VALUE("12:00"),VALUE(P10)<=VALUE("13:59")),"12:00 a 14:00",IF(AND(VALUE(P10)>=VALUE("14:00"),VALUE(P10)<=VALUE("15:59")),"14:00 a 16:00",IF(AND(VALUE(P10)>=VALUE("16:00"),VALUE(P10)<=VALUE("17:59")),"16:00 a 18:00",IF(AND(VALUE(P10)>=VALUE("18:00"),VALUE(P10)<=VALUE("19:59")),"18:00 a 20:00",IF(AND(VALUE(P10)>=VALUE("20:00"),VALUE(P10)<=VALUE("21:59")),"20:00 a 22:00",IF(AND(VALUE(P10)>=VALUE("22:00"),VALUE(P10)<=VALUE("23:59")),"22:00 a 00:00","no corresponde")))))))))))) -> 00:00 a 02:00 | D10: ARGUELLO | E10: CARABAJAL, GRACIELA | F10: 3 | G10: INFANTE, JONATHAN ISMAEL | H10: 919871 | I10: 46737371 | J10: CHACARITA | K10: APARENTE COMERCIALIZACION ESTUPEFACIENTES | M10: LEY 23.737 | N10: CONSTITUCION32 | O10: Constitucion | P10: 0.063194444 | Q10: 0.078472222 | R10: 0.068055556 | S10: - | T10: - | U10: - | V10: - | W10: SE VISUALIZA POR CAMARA CONSTITUCION32 FEMENINO EN APARNETE VENTA DE ESTUPEFACIENTES,SE DA AVISO A COMANDO GENERANDO CARTA SAE N°46737371,ARRIBO DE PERSONAL POLICIAL. SE TOMA CONOCIMIENTO MEDIANTE CARTA SAE: MOVIL AMPLIA QUE SE REALIZO CONSULTA POR ANTE LA UFLA ESTE A/C DR DEBRASSI, DISPUSO ACTUACIONES POR AVERIGUACION COMERCIALIZACION DE ESTUPEFACIENTES. NOTIFICACION DEL FEMENINO. | X10: 0 | Y10: 1 | Z10: 1 | AA10: 1C | AB10: U | AC10: MONITOREO | AE10: 1 IMPUTADO | AF10: FINALIZA CON IMPUTADO/S | AL10: =VLOOKUP(G10,Hoja2!P:Q,2,0) -> 37358594 | AM10: =IF(OR(Y10>0,X10>0),"IMPUTADO","NADA") -> IMPUTADO | AN10: =IF(AND(AM10="IMPUTADO",ISBLANK(M10)),"FALTO","NO") -> NO
A11: 45992 | B11: =IF(AND(VALUE(P11)>=VALUE("06:00"),VALUE(P11)<=VALUE("17:59")),"06 A 18","18 A 06") -> 18 A 06 | C11: =IF(AND(VALUE(P11)>=VALUE("00:00"),VALUE(P11)<=VALUE("01:59")),"00:00 a 02:00",IF(AND(VALUE(P11)>=VALUE("02:00"),VALUE(P11)<=VALUE("03:59")),"02:00 a 04:00",IF(AND(VALUE(P11)>=VALUE("04:00"),VALUE(P11)<=VALUE("05:59")),"04:00 a 06:00",IF(AND(VALUE(P11)>=VALUE("06:00"),VALUE(P11)<=VALUE("07:59")),"06:00 a 08:00",IF(AND(VALUE(P11)>=VALUE("08:00"),VALUE(P11)<=VALUE("09:59")),"08:00 a 10:00",IF(AND(VALUE(P11)>=VALUE("10:00"),VALUE(P11)<=VALUE("11:59")),"10:00 a 12:00",IF(AND(VALUE(P11)>=VALUE("12:00"),VALUE(P11)<=VALUE("13:59")),"12:00 a 14:00",IF(AND(VALUE(P11)>=VALUE("14:00"),VALUE(P11)<=VALUE("15:59")),"14:00 a 16:00",IF(AND(VALUE(P11)>=VALUE("16:00"),VALUE(P11)<=VALUE("17:59")),"16:00 a 18:00",IF(AND(VALUE(P11)>=VALUE("18:00"),VALUE(P11)<=VALUE("19:59")),"18:00 a 20:00",IF(AND(VALUE(P11)>=VALUE("20:00"),VALUE(P11)<=VALUE("21:59")),"20:00 a 22:00",IF(AND(VALUE(P11)>=VALUE("22:00"),VALUE(P11)<=VALUE("23:59")),"22:00 a 00:00","no corresponde")))))))))))) -> 00:00 a 02:00 | D11: ARGUELLO | E11: QUINTANA, GILDA | F11: 3 | G11: SUAREZ, SABRINA | H11: 919868 | I11: 46737459 | J11: CHACARITA | K11: COLABORACION | L11: IDENT. DE PERSONAS | N11: VILLA DEVOTO39 | O11: Villa Devoto | P11: 0.079861111 | Q11: 0.090277778 | R11: 0.08125 | S11: - | T11: - | U11: - | V11: - | W11: SE TOMA CONOCIMIENTO MEDIANTE CARTA SAE SOBRE LLAMANTE APARENTEMENTE EN DEMANDA DE AUXILIO, PERSONAL 911 ESCUCHA DISCUSION NO RESPONDEN AL OPERADOR. SE VISUALIZA UN FEMENNO Y CUATRO MASCULINOS. ARRIBA PERSONAL POLICIAL. PERSONAL INFORMA SE PROCEDE A IDENTIFICAR A LOS MASCULINOS PASADOS DE COPAS CON RESULTADO NEGATIVO SIN ELEMENTOS CONSTITUTIVO DE DELITO PANORAMA NORMAL.- | X11: 0 | Y11: 0 | Z11: 0 | AA11: 11B | AB11: U | AC11: CARTA | AD11: SISEP | AF11: CARTA FINALIZADA | AL11: =VLOOKUP(G11,Hoja2!P:Q,2,0) -> 29382472 | AM11: =IF(OR(Y11>0,X11>0),"IMPUTADO","NADA") -> NADA | AN11: =IF(AND(AM11="IMPUTADO",ISBLANK(M11)),"FALTO","NO") -> NO
A12: 45992 | B12: =IF(AND(VALUE(P12)>=VALUE("06:00"),VALUE(P12)<=VALUE("17:59")),"06 A 18","18 A 06") -> 18 A 06 | C12: =IF(AND(VALUE(P12)>=VALUE("00:00"),VALUE(P12)<=VALUE("01:59")),"00:00 a 02:00",IF(AND(VALUE(P12)>=VALUE("02:00"),VALUE(P12)<=VALUE("03:59")),"02:00 a 04:00",IF(AND(VALUE(P12)>=VALUE("04:00"),VALUE(P12)<=VALUE("05:59")),"04:00 a 06:00",IF(AND(VALUE(P12)>=VALUE("06:00"),VALUE(P12)<=VALUE("07:59")),"06:00 a 08:00",IF(AND(VALUE(P12)>=VALUE("08:00"),VALUE(P12)<=VALUE("09:59")),"08:00 a 10:00",IF(AND(VALUE(P12)>=VALUE("10:00"),VALUE(P12)<=VALUE("11:59")),"10:00 a 12:00",IF(AND(VALUE(P12)>=VALUE("12:00"),VALUE(P12)<=VALUE("13:59")),"12:00 a 14:00",IF(AND(VALUE(P12)>=VALUE("14:00"),VALUE(P12)<=VALUE("15:59")),"14:00 a 16:00",IF(AND(VALUE(P12)>=VALUE("16:00"),VALUE(P12)<=VALUE("17:59")),"16:00 a 18:00",IF(AND(VALUE(P12)>=VALUE("18:00"),VALUE(P12)<=VALUE("19:59")),"18:00 a 20:00",IF(AND(VALUE(P12)>=VALUE("20:00"),VALUE(P12)<=VALUE("21:59")),"20:00 a 22:00",IF(AND(VALUE(P12)>=VALUE("22:00"),VALUE(P12)<=VALUE("23:59")),"22:00 a 00:00","no corresponde")))))))))))) -> 02:00 a 04:00 | D12: ARGUELLO | E12: COLO, NADIA | F12: 3 | G12: BENITEZ PEREIRA, PATRICIA | I12: 46737485 | J12: PUERTO MADERO | K12: ROBO/HURTO | M12: ROBO/HURTO | N12: RECOLETAO109 | O12: Recoleta | P12: 0.083333333 | Q12: 0.10972222 | R12: 0.086805556 | S12: - | T12: - | U12: - | V12: - | W12: SE TOMA CONOCIMIENTO MEDIANTE CARTA SAE QUE UN MASCULINO ESTABA SUSTRAYENDO COBRE. SE VISUALIZO RETIRARSE DEL MISMO Y AL GIRAR SOBRE CALLE BUSTAMANTE PERSONAL POLICIAL DA CON EL MISMO. SE LABRAN ACTUACIONES POR ROBO PROCEDIENDO A LA DETENCION DEL MASCULINO. SE SECUESTRA PICAPORTE SUSTRAIDO, UN CUCHILLO, DESTORNILLADOR Y UN PEDAZO DE MADERA.- | X12: 0 | Y12: 1 | Z12: 1 | AA12: 2A | AB12: U | AC12: CARTA | AD12: SISEP | AE12: 1 DETENIDO | AF12: FINALIZA CON IMPUTADO/S | AL12: =VLOOKUP(G12,Hoja2!P:Q,2,0) -> 39339538 | AM12: =IF(OR(Y12>0,X12>0),"IMPUTADO","NADA") -> IMPUTADO | AN12: =IF(AND(AM12="IMPUTADO",ISBLANK(M12)),"FALTO","NO") -> NO
A13: 45992 | B13: =IF(AND(VALUE(P13)>=VALUE("06:00"),VALUE(P13)<=VALUE("17:59")),"06 A 18","18 A 06") -> 18 A 06 | C13: =IF(AND(VALUE(P13)>=VALUE("00:00"),VALUE(P13)<=VALUE("01:59")),"00:00 a 02:00",IF(AND(VALUE(P13)>=VALUE("02:00"),VALUE(P13)<=VALUE("03:59")),"02:00 a 04:00",IF(AND(VALUE(P13)>=VALUE("04:00"),VALUE(P13)<=VALUE("05:59")),"04:00 a 06:00",IF(AND(VALUE(P13)>=VALUE("06:00"),VALUE(P13)<=VALUE("07:59")),"06:00 a 08:00",IF(AND(VALUE(P13)>=VALUE("08:00"),VALUE(P13)<=VALUE("09:59")),"08:00 a 10:00",IF(AND(VALUE(P13)>=VALUE("10:00"),VALUE(P13)<=VALUE("11:59")),"10:00 a 12:00",IF(AND(VALUE(P13)>=VALUE("12:00"),VALUE(P13)<=VALUE("13:59")),"12:00 a 14:00",IF(AND(VALUE(P13)>=VALUE("14:00"),VALUE(P13)<=VALUE("15:59")),"14:00 a 16:00",IF(AND(VALUE(P13)>=VALUE("16:00"),VALUE(P13)<=VALUE("17:59")),"16:00 a 18:00",IF(AND(VALUE(P13)>=VALUE("18:00"),VALUE(P13)<=VALUE("19:59")),"18:00 a 20:00",IF(AND(VALUE(P13)>=VALUE("20:00"),VALUE(P13)<=VALUE("21:59")),"20:00 a 22:00",IF(AND(VALUE(P13)>=VALUE("22:00"),VALUE(P13)<=VALUE("23:59")),"22:00 a 00:00","no corresponde")))))))))))) -> 02:00 a 04:00 | D13: ARGUELLO | E13: ALCARAZ, ARIEL | F13: 3 | G13: LOBOS, LUCRECIA | H13: 919866 | I13: 46737489 | J13: CHACARITA | K13: INCIDENCIA EN VIA PUBLICA | M13: LESIONES | N13: BALVANERA21 | O13: Balvanera | P13: 0.084027778 | Q13: 0.10069444 | R13: 0.0875 | S13: - | T13: - | U13: - | V13: - | W13: SE TOMA CONOCIMIENTO MEDIANTE CARTA SAE SOBRE DENUNCIANTE QUIEN REFIERE QUE HABRIA UN MASCULINO GOLPEANDO A UN FEMENINO EN LA VIA PUBLICA. HABRIA OTRO MASCULINO INTENTANDO DEFENDER AL FEMENINO DE LAS AGRESIONES. SE VISUALIZA DOS MASCULINOS EN INCIDENCIA. ARRIBA PERSONAL POLICIAL. SE INFORMA NEGATIVO IVOLENCIA DE GENERO SE TRATO DE UNA INCIDENCIA. AMBAS PARTES ILESAS. SE TOMA CONOCIMIENTO QUE SE LABRAN ACTUACIONES POR LESIONES 89 AGRAVADA POR ARTICULO 92. AVALA DETENCION DEL FEMENINO.- | X13: 0 | Y13: 1 | Z13: 0 | AA13: 3B | AB13: U | AC13: CARTA | AD13: SISEP | AE13: 1 DETENIDO | AF13: FINALIZA CON IMPUTADO/S | AL13: =VLOOKUP(G13,Hoja2!P:Q,2,0) -> 28898771 | AM13: =IF(OR(Y13>0,X13>0),"IMPUTADO","NADA") -> IMPUTADO | AN13: =IF(AND(AM13="IMPUTADO",ISBLANK(M13)),"FALTO","NO") -> NO
A14: 45992 | B14: =IF(AND(VALUE(P14)>=VALUE("06:00"),VALUE(P14)<=VALUE("17:59")),"06 A 18","18 A 06") -> 18 A 06 | C14: =IF(AND(VALUE(P14)>=VALUE("00:00"),VALUE(P14)<=VALUE("01:59")),"00:00 a 02:00",IF(AND(VALUE(P14)>=VALUE("02:00"),VALUE(P14)<=VALUE("03:59")),"02:00 a 04:00",IF(AND(VALUE(P14)>=VALUE("04:00"),VALUE(P14)<=VALUE("05:59")),"04:00 a 06:00",IF(AND(VALUE(P14)>=VALUE("06:00"),VALUE(P14)<=VALUE("07:59")),"06:00 a 08:00",IF(AND(VALUE(P14)>=VALUE("08:00"),VALUE(P14)<=VALUE("09:59")),"08:00 a 10:00",IF(AND(VALUE(P14)>=VALUE("10:00"),VALUE(P14)<=VALUE("11:59")),"10:00 a 12:00",IF(AND(VALUE(P14)>=VALUE("12:00"),VALUE(P14)<=VALUE("13:59")),"12:00 a 14:00",IF(AND(VALUE(P14)>=VALUE("14:00"),VALUE(P14)<=VALUE("15:59")),"14:00 a 16:00",IF(AND(VALUE(P14)>=VALUE("16:00"),VALUE(P14)<=VALUE("17:59")),"16:00 a 18:00",IF(AND(VALUE(P14)>=VALUE("18:00"),VALUE(P14)<=VALUE("19:59")),"18:00 a 20:00",IF(AND(VALUE(P14)>=VALUE("20:00"),VALUE(P14)<=VALUE("21:59")),"20:00 a 22:00",IF(AND(VALUE(P14)>=VALUE("22:00"),VALUE(P14)<=VALUE("23:59")),"22:00 a 00:00","no corresponde")))))))))))) -> 02:00 a 04:00 | D14: ARGUELLO | E14: ALCARAZ, ARIEL | F14: 3 | G14: SUAREZ, SABRINA | H14: 919865 | I14: 46737542 | J14: CHACARITA | K14: INCIDENCIA EN VIA PUBLICA | N14: VILLA LURO24 / 05 CAM02 | O14: Villa Luro | P14: 0.092361111 | Q14: 0.10902778 | R14: 0.098611111 | S14: - | T14: - | U14: - | V14: - | W14: SE TOMA CONOCIMIENTO MEDIANTE CARTA SAE SOBRE DENUNCIANTE QUIEN REFIER EQUE HABRIA ESCUCHADO CUATRO DETONACIONES Y GRITOS DE UNA PERSONA, REFIERE QUE HABRIA MATADO A ALGUIEN, WESCUCHA GRITOS DE VARIAS PERSONAS. SEVISUALIZA TRES MASCULINOS DE SIMILARES CARACTERISTICAS A LAS APORTADAS EN CARTA. LOS MISMOS EN BICICLETA. ARRIBA PERSONAL POLICIAL DANDO CON LOS MISMOS. VERIFICADA LINEA DE TIEMPO OBSERVANDO A ESTOS DESCARTANDO ALGUN TIPO DE ELEMENTO EN UN CONTENEDOR DE RESIDUOS. SE INFORMA SE PROCEDE A IDENTIFICAR A TRES MASCULINOS CON RESULTADO NEGATIVO . NEGATIVO ELEMENTO CONSTITUTIVO DE DELITO. SE RETIRAN SIN NOVEDAD PANORAMA NORMAL.- | X14: 0 | Y14: 0 | Z14: 0 | AA14: 10C | AB14: U | AC14: CARTA | AF14: CARTA FINALIZADA | AL14: =VLOOKUP(G14,Hoja2!P:Q,2,0) -> 29382472 | AM14: =IF(OR(Y14>0,X14>0),"IMPUTADO","NADA") -> NADA | AN14: =IF(AND(AM14="IMPUTADO",ISBLANK(M14)),"FALTO","NO") -> NO
A15: 45992 | B15: =IF(AND(VALUE(P15)>=VALUE("06:00"),VALUE(P15)<=VALUE("17:59")),"06 A 18","18 A 06") -> 18 A 06 | C15: =IF(AND(VALUE(P15)>=VALUE("00:00"),VALUE(P15)<=VALUE("01:59")),"00:00 a 02:00",IF(AND(VALUE(P15)>=VALUE("02:00"),VALUE(P15)<=VALUE("03:59")),"02:00 a 04:00",IF(AND(VALUE(P15)>=VALUE("04:00"),VALUE(P15)<=VALUE("05:59")),"04:00 a 06:00",IF(AND(VALUE(P15)>=VALUE("06:00"),VALUE(P15)<=VALUE("07:59")),"06:00 a 08:00",IF(AND(VALUE(P15)>=VALUE("08:00"),VALUE(P15)<=VALUE("09:59")),"08:00 a 10:00",IF(AND(VALUE(P15)>=VALUE("10:00"),VALUE(P15)<=VALUE("11:59")),"10:00 a 12:00",IF(AND(VALUE(P15)>=VALUE("12:00"),VALUE(P15)<=VALUE("13:59")),"12:00 a 14:00",IF(AND(VALUE(P15)>=VALUE("14:00"),VALUE(P15)<=VALUE("15:59")),"14:00 a 16:00",IF(AND(VALUE(P15)>=VALUE("16:00"),VALUE(P15)<=VALUE("17:59")),"16:00 a 18:00",IF(AND(VALUE(P15)>=VALUE("18:00"),VALUE(P15)<=VALUE("19:59")),"18:00 a 20:00",IF(AND(VALUE(P15)>=VALUE("20:00"),VALUE(P15)<=VALUE("21:59")),"20:00 a 22:00",IF(AND(VALUE(P15)>=VALUE("22:00"),VALUE(P15)<=VALUE("23:59")),"22:00 a 00:00","no corresponde")))))))))))) -> 02:00 a 04:00 | D15: ARGUELLO | E15: QUINTANA, GILDA | F15: 3 | G15: LOBOS, LUCRECIA | H15: 919858 | I15: 46737617 | J15: CHACARITA | K15: IDENTIFICACION DE PERSONAS | N15: BALVANERA35 | O15: Balvanera | P15: 0.10833333 | Q15: 0.11319444 | R15: 0.10972222 | S15: - | T15: - | U15: - | V15: - | W15: SE VISUALIZA UN MASCULINO TENDIDO EN LA ACERA APARENTEMENTE EN ESTADO DE EBRIEDAD EXHIBIENDO PARTES INTIMAS. ARRIBA PERSONAL POLICIAL. SE INFORMA SE TRATA DE MASCULINOS EN SITUACION VULNERABLE LOS CUALES SE RETIRAN DE FORMA AMABLE. SIN NOVEDAD.- | X15: 0 | Y15: 0 | Z15: 0 | AA15: 3A | AB15: U | AC15: MONITOREO | AF15: CARTA FINALIZADA | AL15: =VLOOKUP(G15,Hoja2!P:Q,2,0) -> 28898771 | AM15: =IF(OR(Y15>0,X15>0),"IMPUTADO","NADA") -> NADA | AN15: =IF(AND(AM15="IMPUTADO",ISBLANK(M15)),"FALTO","NO") -> NO
A16: 45992 | B16: =IF(AND(VALUE(P16)>=VALUE("06:00"),VALUE(P16)<=VALUE("17:59")),"06 A 18","18 A 06") -> 18 A 06 | C16: =IF(AND(VALUE(P16)>=VALUE("00:00"),VALUE(P16)<=VALUE("01:59")),"00:00 a 02:00",IF(AND(VALUE(P16)>=VALUE("02:00"),VALUE(P16)<=VALUE("03:59")),"02:00 a 04:00",IF(AND(VALUE(P16)>=VALUE("04:00"),VALUE(P16)<=VALUE("05:59")),"04:00 a 06:00",IF(AND(VALUE(P16)>=VALUE("06:00"),VALUE(P16)<=VALUE("07:59")),"06:00 a 08:00",IF(AND(VALUE(P16)>=VALUE("08:00"),VALUE(P16)<=VALUE("09:59")),"08:00 a 10:00",IF(AND(VALUE(P16)>=VALUE("10:00"),VALUE(P16)<=VALUE("11:59")),"10:00 a 12:00",IF(AND(VALUE(P16)>=VALUE("12:00"),VALUE(P16)<=VALUE("13:59")),"12:00 a 14:00",IF(AND(VALUE(P16)>=VALUE("14:00"),VALUE(P16)<=VALUE("15:59")),"14:00 a 16:00",IF(AND(VALUE(P16)>=VALUE("16:00"),VALUE(P16)<=VALUE("17:59")),"16:00 a 18:00",IF(AND(VALUE(P16)>=VALUE("18:00"),VALUE(P16)<=VALUE("19:59")),"18:00 a 20:00",IF(AND(VALUE(P16)>=VALUE("20:00"),VALUE(P16)<=VALUE("21:59")),"20:00 a 22:00",IF(AND(VALUE(P16)>=VALUE("22:00"),VALUE(P16)<=VALUE("23:59")),"22:00 a 00:00","no corresponde")))))))))))) -> 02:00 a 04:00 | D16: ARGUELLO | E16: QUINTANA, GILDA | F16: 3 | G16: CACERES, MATIAS NAHUEL | H16: 919853 | I16: 46737683 | J16: CHACARITA | K16: ROBO/HURTO | M16: ROBO/HURTO | N16: PALERMO O151 | O16: Palermo | P16: 0.125 | Q16: 0.16666667 | R16: 0.12708333 | S16: - | T16: - | U16: - | V16: - | W16: SE TOMA CONOCIMIENTO MEDIANTE CARTA SAE SOBRE DENUNCIANTE QUIEN REFIERE QUE HABRIA UN MASCULINO ELCUAL ROMPIO EL VIDRIODE U NVEHICULO TOYOUA ESTACIONADO EN LA VIA PUBLICA. SE VISUALIZ MASCULINO DE SIMILARES CARACTERISTICAS EN EL LUGAR. SEGUIDAMENTE SE VERIFICALINEA DE TIEMPO OBSERVANDO AL AMSCULINO APROXIMARSE AL VEHICULO E INTRODUCIR PARTE DEL TORSO PARA LUEGO RETIRARSE SIN LOGRAR OBSERVAR SI SUSTRAE ALGUN TIPO DE ELEMENTO. ARRIBA PERSONAL POLICIAL. SE INFORMA SE HALOLA VEHICULO CON PARABRISASA TRASERO VIOLENTADO.Posteriormente se toma conocimiento mediante la ampliación de la carta SAE Fiscalía n°29 a cargo del Dr. Herrera secretaria única a cargo de la Dra. Tedezco actuaciones en flagrancia con tentativa de robo | X16: 0 | Y16: 1 | Z16: 0 | AA16: 14A | AB16: U | AC16: CARTA | AD16: SISEP | AE16: 1 DETENIDO | AF16: FINALIZA CON IMPUTADO/S | AL16: =VLOOKUP(G16,Hoja2!P:Q,2,0) -> 42930433 | AM16: =IF(OR(Y16>0,X16>0),"IMPUTADO","NADA") -> IMPUTADO | AN16: =IF(AND(AM16="IMPUTADO",ISBLANK(M16)),"FALTO","NO") -> NO
A17: 45992 | B17: =IF(AND(VALUE(P17)>=VALUE("06:00"),VALUE(P17)<=VALUE("17:59")),"06 A 18","18 A 06") -> 18 A 06 | C17: =IF(AND(VALUE(P17)>=VALUE("00:00"),VALUE(P17)<=VALUE("01:59")),"00:00 a 02:00",IF(AND(VALUE(P17)>=VALUE("02:00"),VALUE(P17)<=VALUE("03:59")),"02:00 a 04:00",IF(AND(VALUE(P17)>=VALUE("04:00"),VALUE(P17)<=VALUE("05:59")),"04:00 a 06:00",IF(AND(VALUE(P17)>=VALUE("06:00"),VALUE(P17)<=VALUE("07:59")),"06:00 a 08:00",IF(AND(VALUE(P17)>=VALUE("08:00"),VALUE(P17)<=VALUE("09:59")),"08:00 a 10:00",IF(AND(VALUE(P17)>=VALUE("10:00"),VALUE(P17)<=VALUE("11:59")),"10:00 a 12:00",IF(AND(VALUE(P17)>=VALUE("12:00"),VALUE(P17)<=VALUE("13:59")),"12:00 a 14:00",IF(AND(VALUE(P17)>=VALUE("14:00"),VALUE(P17)<=VALUE("15:59")),"14:00 a 16:00",IF(AND(VALUE(P17)>=VALUE("16:00"),VALUE(P17)<=VALUE("17:59")),"16:00 a 18:00",IF(AND(VALUE(P17)>=VALUE("18:00"),VALUE(P17)<=VALUE("19:59")),"18:00 a 20:00",IF(AND(VALUE(P17)>=VALUE("20:00"),VALUE(P17)<=VALUE("21:59")),"20:00 a 22:00",IF(AND(VALUE(P17)>=VALUE("22:00"),VALUE(P17)<=VALUE("23:59")),"22:00 a 00:00","no corresponde")))))))))))) -> 02:00 a 04:00 | D17: ARGUELLO | E17: QUINTANA, GILDA | F17: 3 | G17: CUELLAR, CAMILA | H17: 919842 | I17: 46737728 | J17: CHACARITA | K17: COLABORACION | L17: IDENT. VEHICULAR | N17: PARQUE CHACABUCO71 | O17: Parque Chacabuco | P17: 0.13402778 | Q17: 0.13819444 | R17: 0.13402778 | S17: - | T17: - | U17: - | V17: - | W17: SE TOMA CONOCIMIENTO MEDIANTE CARTA SAE SOBRE DENUNCIANTE QUIEN REFIERE QUE HABRIA UN AUTOMOVIL ESTACIONADO EN SITUACION EXTRAÑA HABRIAN CINCO PERSONAS EN EL VEHICULO. ESTARIAN ALCOHOLIZADOS. SE VISUALIZA SARRIBO DE PERSONAL POLICIAL. SE INFORMA SE TRATO DE VEHICULO CON PROBLEMAS MECANICOS. SE ENCUENTRA AGUARDANDO GRUA.- | X17: 0 | Y17: 0 | Z17: 0 | AA17: 7B | AB17: U | AC17: CARTA | AF17: CARTA FINALIZADA | AL17: =VLOOKUP(G17,Hoja2!P:Q,2,0) -> 46280094 | AM17: =IF(OR(Y17>0,X17>0),"IMPUTADO","NADA") -> NADA | AN17: =IF(AND(AM17="IMPUTADO",ISBLANK(M17)),"FALTO","NO") -> NO
A18: 45992 | B18: =IF(AND(VALUE(P18)>=VALUE("06:00"),VALUE(P18)<=VALUE("17:59")),"06 A 18","18 A 06") -> 18 A 06 | C18: =IF(AND(VALUE(P18)>=VALUE("00:00"),VALUE(P18)<=VALUE("01:59")),"00:00 a 02:00",IF(AND(VALUE(P18)>=VALUE("02:00"),VALUE(P18)<=VALUE("03:59")),"02:00 a 04:00",IF(AND(VALUE(P18)>=VALUE("04:00"),VALUE(P18)<=VALUE("05:59")),"04:00 a 06:00",IF(AND(VALUE(P18)>=VALUE("06:00"),VALUE(P18)<=VALUE("07:59")),"06:00 a 08:00",IF(AND(VALUE(P18)>=VALUE("08:00"),VALUE(P18)<=VALUE("09:59")),"08:00 a 10:00",IF(AND(VALUE(P18)>=VALUE("10:00"),VALUE(P18)<=VALUE("11:59")),"10:00 a 12:00",IF(AND(VALUE(P18)>=VALUE("12:00"),VALUE(P18)<=VALUE("13:59")),"12:00 a 14:00",IF(AND(VALUE(P18)>=VALUE("14:00"),VALUE(P18)<=VALUE("15:59")),"14:00 a 16:00",IF(AND(VALUE(P18)>=VALUE("16:00"),VALUE(P18)<=VALUE("17:59")),"16:00 a 18:00",IF(AND(VALUE(P18)>=VALUE("18:00"),VALUE(P18)<=VALUE("19:59")),"18:00 a 20:00",IF(AND(VALUE(P18)>=VALUE("20:00"),VALUE(P18)<=VALUE("21:59")),"20:00 a 22:00",IF(AND(VALUE(P18)>=VALUE("22:00"),VALUE(P18)<=VALUE("23:59")),"22:00 a 00:00","no corresponde")))))))))))) -> 02:00 a 04:00 | D18: ARGUELLO | E18: QUINTANA, GILDA | F18: 3 | G18: GONZALEZ, ARACELI | H18: 919891 | I18: 46737754 | J18: CHACARITA | K18: IDENTIFICACION DE PERSONAS | N18: BALVANERA 44 | O18: Balvanera | P18: 0.13402778 | Q18: 0.14166667 | R18: 0.13819444 | S18: - | T18: - | U18: - | V18: - | W18: SE TOMA CONOCIMIENTO MEDIANTE CARTA SAE SOBRE DENUNCIANTE QUIEN REFIERE QUE HABRIA UNA PERSONA QUE SE ENCUENTRA TOCANDO EL TIMBRE DEL DEPARTAMENTO. SE VISUALIZA FEMENINO Y MASCULINO EN CERCANIAS DE INGRESO DE EDIFICIO. ARRIBA PERSONAL POLICIAL. SE INFORMA SE IDENTIFICA SIN NOVEDAD. PANORAMA NORMAL.- | X18: 0 | Y18: 0 | Z18: 0 | AA18: 3C | AB18: U | AC18: CARTA | AD18: SISEP | AF18: CARTA FINALIZADA | AL18: =VLOOKUP(G18,Hoja2!P:Q,2,0) -> 94914642 | AM18: =IF(OR(Y18>0,X18>0),"IMPUTADO","NADA") -> NADA | AN18: =IF(AND(AM18="IMPUTADO",ISBLANK(M18)),"FALTO","NO") -> NO
A19: 45992 | B19: =IF(AND(VALUE(P19)>=VALUE("06:00"),VALUE(P19)<=VALUE("17:59")),"06 A 18","18 A 06") -> 18 A 06 | C19: =IF(AND(VALUE(P19)>=VALUE("00:00"),VALUE(P19)<=VALUE("01:59")),"00:00 a 02:00",IF(AND(VALUE(P19)>=VALUE("02:00"),VALUE(P19)<=VALUE("03:59")),"02:00 a 04:00",IF(AND(VALUE(P19)>=VALUE("04:00"),VALUE(P19)<=VALUE("05:59")),"04:00 a 06:00",IF(AND(VALUE(P19)>=VALUE("06:00"),VALUE(P19)<=VALUE("07:59")),"06:00 a 08:00",IF(AND(VALUE(P19)>=VALUE("08:00"),VALUE(P19)<=VALUE("09:59")),"08:00 a 10:00",IF(AND(VALUE(P19)>=VALUE("10:00"),VALUE(P19)<=VALUE("11:59")),"10:00 a 12:00",IF(AND(VALUE(P19)>=VALUE("12:00"),VALUE(P19)<=VALUE("13:59")),"12:00 a 14:00",IF(AND(VALUE(P19)>=VALUE("14:00"),VALUE(P19)<=VALUE("15:59")),"14:00 a 16:00",IF(AND(VALUE(P19)>=VALUE("16:00"),VALUE(P19)<=VALUE("17:59")),"16:00 a 18:00",IF(AND(VALUE(P19)>=VALUE("18:00"),VALUE(P19)<=VALUE("19:59")),"18:00 a 20:00",IF(AND(VALUE(P19)>=VALUE("20:00"),VALUE(P19)<=VALUE("21:59")),"20:00 a 22:00",IF(AND(VALUE(P19)>=VALUE("22:00"),VALUE(P19)<=VALUE("23:59")),"22:00 a 00:00","no corresponde")))))))))))) -> 02:00 a 04:00 | D19: ARGUELLO | E19: QUINTANA, GILDA | F19: 3 | G19: FEDELLE, SANDRA ANALIA | H19: 919844 | I19: 46737810 | J19: CHACARITA | K19: IDENTIFICACION DE PERSONAS | N19: VILLA CRESPO10 | O19: Villa Crespo | P19: 0.15069444 | Q19: 0.15763889 | R19: 0.15277778 | S19: - | T19: - | U19: - | V19: - | W19: SE TOMA CONOCIMIENTO MEDIANTE CARTA SAE SOBRE DENUNCIANTE QUIEN REFIERE QUE HABRIA UN AUTO ESTACIONADO EN CONTRAMANO. SE VISUALIZAVEHICULO APORTADO REALIZANDO MANIOBRAS PELIGROSAS SOBRE AV. CORRIENTES. ARRIBA PERSONAL POLICIAL REFIERE SIN NOVEDAD. MASCULINO SE HABIA EQUIVOCADO DE SENTIDO.- | X19: 0 | Y19: 0 | Z19: 0 | AA19: 15B | AB19: U | AC19: CARTA | AD19: SISEP | AF19: CARTA FINALIZADA | AL19: =VLOOKUP(G19,Hoja2!P:Q,2,0) -> 34210219 | AM19: =IF(OR(Y19>0,X19>0),"IMPUTADO","NADA") -> NADA | AN19: =IF(AND(AM19="IMPUTADO",ISBLANK(M19)),"FALTO","NO") -> NO
A20: 45992 | B20: =IF(AND(VALUE(P20)>=VALUE("06:00"),VALUE(P20)<=VALUE("17:59")),"06 A 18","18 A 06") -> 18 A 06 | C20: =IF(AND(VALUE(P20)>=VALUE("00:00"),VALUE(P20)<=VALUE("01:59")),"00:00 a 02:00",IF(AND(VALUE(P20)>=VALUE("02:00"),VALUE(P20)<=VALUE("03:59")),"02:00 a 04:00",IF(AND(VALUE(P20)>=VALUE("04:00"),VALUE(P20)<=VALUE("05:59")),"04:00 a 06:00",IF(AND(VALUE(P20)>=VALUE("06:00"),VALUE(P20)<=VALUE("07:59")),"06:00 a 08:00",IF(AND(VALUE(P20)>=VALUE("08:00"),VALUE(P20)<=VALUE("09:59")),"08:00 a 10:00",IF(AND(VALUE(P20)>=VALUE("10:00"),VALUE(P20)<=VALUE("11:59")),"10:00 a 12:00",IF(AND(VALUE(P20)>=VALUE("12:00"),VALUE(P20)<=VALUE("13:59")),"12:00 a 14:00",IF(AND(VALUE(P20)>=VALUE("14:00"),VALUE(P20)<=VALUE("15:59")),"14:00 a 16:00",IF(AND(VALUE(P20)>=VALUE("16:00"),VALUE(P20)<=VALUE("17:59")),"16:00 a 18:00",IF(AND(VALUE(P20)>=VALUE("18:00"),VALUE(P20)<=VALUE("19:59")),"18:00 a 20:00",IF(AND(VALUE(P20)>=VALUE("20:00"),VALUE(P20)<=VALUE("21:59")),"20:00 a 22:00",IF(AND(VALUE(P20)>=VALUE("22:00"),VALUE(P20)<=VALUE("23:59")),"22:00 a 00:00","no corresponde")))))))))))) -> 02:00 a 04:00 | D20: ARGUELLO | E20: QUINTANA, GILDA | F20: 3 | G20: CACERES, MATIAS NAHUEL | H20: 919864 | I20: 46737880 | J20: CHACARITA | K20: COLABORACION | L20: INCIDENCIA | N20: PALERMO90 | O20: Palermo | P20: 0.16388889 | Q20: 0.17152778 | R20: 0.16527778 | S20: - | T20: - | U20: - | V20: - | W20: SE VISUALIZA PERSONAL POLICIAL INGRESANDO A ESTACION DE FERROCARRIL, ESTACION PALERMO, SE VISUALIZA INCIDENCIA ENTRE DOS PERSONAS EN AL VIA PUBLICA..HT INF QUE SE TRATO INCIDENCIA ENTRE MASCULINOS, LOS MISMOS SE RETIRAN SIN APORTAR DATOS.- | X20: 0 | Y20: 0 | Z20: 0 | AA20: 14B | AB20: U | AC20: MONITOREO | AD20: SISEP | AF20: CARTA FINALIZADA | AL20: =VLOOKUP(G20,Hoja2!P:Q,2,0) -> 42930433 | AM20: =IF(OR(Y20>0,X20>0),"IMPUTADO","NADA") -> NADA | AN20: =IF(AND(AM20="IMPUTADO",ISBLANK(M20)),"FALTO","NO") -> NO
A21: 45992 | B21: =IF(AND(VALUE(P21)>=VALUE("06:00"),VALUE(P21)<=VALUE("17:59")),"06 A 18","18 A 06") -> 18 A 06 | C21: =IF(AND(VALUE(P21)>=VALUE("00:00"),VALUE(P21)<=VALUE("01:59")),"00:00 a 02:00",IF(AND(VALUE(P21)>=VALUE("02:00"),VALUE(P21)<=VALUE("03:59")),"02:00 a 04:00",IF(AND(VALUE(P21)>=VALUE("04:00"),VALUE(P21)<=VALUE("05:59")),"04:00 a 06:00",IF(AND(VALUE(P21)>=VALUE("06:00"),VALUE(P21)<=VALUE("07:59")),"06:00 a 08:00",IF(AND(VALUE(P21)>=VALUE("08:00"),VALUE(P21)<=VALUE("09:59")),"08:00 a 10:00",IF(AND(VALUE(P21)>=VALUE("10:00"),VALUE(P21)<=VALUE("11:59")),"10:00 a 12:00",IF(AND(VALUE(P21)>=VALUE("12:00"),VALUE(P21)<=VALUE("13:59")),"12:00 a 14:00",IF(AND(VALUE(P21)>=VALUE("14:00"),VALUE(P21)<=VALUE("15:59")),"14:00 a 16:00",IF(AND(VALUE(P21)>=VALUE("16:00"),VALUE(P21)<=VALUE("17:59")),"16:00 a 18:00",IF(AND(VALUE(P21)>=VALUE("18:00"),VALUE(P21)<=VALUE("19:59")),"18:00 a 20:00",IF(AND(VALUE(P21)>=VALUE("20:00"),VALUE(P21)<=VALUE("21:59")),"20:00 a 22:00",IF(AND(VALUE(P21)>=VALUE("22:00"),VALUE(P21)<=VALUE("23:59")),"22:00 a 00:00","no corresponde")))))))))))) -> 04:00 a 06:00 | D21: ARGUELLO | E21: CORTES SEBASTIAN | F21: 3 | G21: FERREYRA, SONIA CRISTINA | H21: 919889 | I21: 46737944 | J21: VILLA LUGANO | K21: IDENTIFICACION DE PERSONAS | N21: NUEVA POMPEYA 72 | O21: Nueva Pompeya | P21: 0.17569444 | Q21: 0.18888889 | R21: 0.17847222 | W21: SE VISUALIZA POR CAMARA NUEVA POMPEYA 72 UN MASCULINO JUNTO A UN FEMENINO AMBOS DE MANERA EXTRAÑA AL LADO DE UN MOTOVEHICULO OBSERVANDO PARA LA ESQUINA DE MOM SE DA AVISO A COMANDO GENERAN CARTA SAE MASCULINO DE ROPAS OSCURAS Y CASCO NEGRO FEMNINO DE CAMPERA NEGRA PANTALON DE JEANS AZUL CASCO NEGRO Y BLANCO CON DETALLES ROSAS Y UNA BOLSA BLANCA EN LA MANO SE VISUALIZA EL ARRIBO DE PERSONAL 904 INF SE IDENTIFICO A LAS PERSONAS Y EL MOTOVEHICULO LOS CUALES CORRESPONDEN Y NO POSEEN IMPEDIMENTOS,PNA NORMAL | X21: 0 | Y21: 0 | Z21: 0 | AA21: 4A | AB21: U | AC21: MONITOREO | AF21: CARTA FINALIZADA | AL21: =VLOOKUP(G21,Hoja2!P:Q,2,0) -> 30461376 | AM21: =IF(OR(Y21>0,X21>0),"IMPUTADO","NADA") -> NADA | AN21: =IF(AND(AM21="IMPUTADO",ISBLANK(M21)),"FALTO","NO") -> NO
A22: 45992 | B22: =IF(AND(VALUE(P22)>=VALUE("06:00"),VALUE(P22)<=VALUE("17:59")),"06 A 18","18 A 06") -> 18 A 06 | C22: =IF(AND(VALUE(P22)>=VALUE("00:00"),VALUE(P22)<=VALUE("01:59")),"00:00 a 02:00",IF(AND(VALUE(P22)>=VALUE("02:00"),VALUE(P22)<=VALUE("03:59")),"02:00 a 04:00",IF(AND(VALUE(P22)>=VALUE("04:00"),VALUE(P22)<=VALUE("05:59")),"04:00 a 06:00",IF(AND(VALUE(P22)>=VALUE("06:00"),VALUE(P22)<=VALUE("07:59")),"06:00 a 08:00",IF(AND(VALUE(P22)>=VALUE("08:00"),VALUE(P22)<=VALUE("09:59")),"08:00 a 10:00",IF(AND(VALUE(P22)>=VALUE("10:00"),VALUE(P22)<=VALUE("11:59")),"10:00 a 12:00",IF(AND(VALUE(P22)>=VALUE("12:00"),VALUE(P22)<=VALUE("13:59")),"12:00 a 14:00",IF(AND(VALUE(P22)>=VALUE("14:00"),VALUE(P22)<=VALUE("15:59")),"14:00 a 16:00",IF(AND(VALUE(P22)>=VALUE("16:00"),VALUE(P22)<=VALUE("17:59")),"16:00 a 18:00",IF(AND(VALUE(P22)>=VALUE("18:00"),VALUE(P22)<=VALUE("19:59")),"18:00 a 20:00",IF(AND(VALUE(P22)>=VALUE("20:00"),VALUE(P22)<=VALUE("21:59")),"20:00 a 22:00",IF(AND(VALUE(P22)>=VALUE("22:00"),VALUE(P22)<=VALUE("23:59")),"22:00 a 00:00","no corresponde")))))))))))) -> 04:00 a 06:00 | D22: ARGUELLO | E22: ALCARAZ, ARIEL | F22: 3 | G22: SCHIRRIPA, ESTEBAN | H22: 919886 | I22: 46737973 | J22: CHACARITA | K22: ROBO/HURTO | M22: ROBO/HURTO | N22: ALMAGRO O175 | O22: Almagro | P22: 0.18819444 | Q22: 0.19027778 | R22: 0.18819444 | S22: - | T22: - | U22: - | V22: - | W22: SE TOMA CONOCIMIENTO MEDIANTE CARTA SAE OSBRE DENUNCIANTE QUIEN REFIERE QUE HABRIA UN MASCULINO ROBANDO A UNN AUTOMOVIL. SE ROBO DOS CAJAS Y UNA MOCHILA DEL INTERIOR DE LA MISMA Y LUEGO SE DA A LA FUGA. SE VISUALIZA MASCULINO PORTANDO UAN CAJA COLOR MARRON Y UNA MOCHILA DESPLAZANDOSE DANDOSE A LA FUGA. ARRIBA PERSONAL POLICIAL DANDO CON EL MISMO. PERSONAL INFORMA EL MASCULINO POSEE UN ESTEREO DEL VEHICULO Y DOS CAJAS DE CARTON. ACTUACIONES TTVA ROBO | X22: 0 | Y22: 1 | Z22: 0 | AA22: 5A | AB22: U | AC22: CARTA | AD22: SISEP | AE22: 1 DETENIDO.- | AF22: FINALIZA CON IMPUTADO/S | AL22: =VLOOKUP(G22,Hoja2!P:Q,2,0) -> 22310347 | AM22: =IF(OR(Y22>0,X22>0),"IMPUTADO","NADA") -> IMPUTADO | AN22: =IF(AND(AM22="IMPUTADO",ISBLANK(M22)),"FALTO","NO") -> NO
A23: 45992 | B23: =IF(AND(VALUE(P23)>=VALUE("06:00"),VALUE(P23)<=VALUE("17:59")),"06 A 18","18 A 06") -> 18 A 06 | C23: =IF(AND(VALUE(P23)>=VALUE("00:00"),VALUE(P23)<=VALUE("01:59")),"00:00 a 02:00",IF(AND(VALUE(P23)>=VALUE("02:00"),VALUE(P23)<=VALUE("03:59")),"02:00 a 04:00",IF(AND(VALUE(P23)>=VALUE("04:00"),VALUE(P23)<=VALUE("05:59")),"04:00 a 06:00",IF(AND(VALUE(P23)>=VALUE("06:00"),VALUE(P23)<=VALUE("07:59")),"06:00 a 08:00",IF(AND(VALUE(P23)>=VALUE("08:00"),VALUE(P23)<=VALUE("09:59")),"08:00 a 10:00",IF(AND(VALUE(P23)>=VALUE("10:00"),VALUE(P23)<=VALUE("11:59")),"10:00 a 12:00",IF(AND(VALUE(P23)>=VALUE("12:00"),VALUE(P23)<=VALUE("13:59")),"12:00 a 14:00",IF(AND(VALUE(P23)>=VALUE("14:00"),VALUE(P23)<=VALUE("15:59")),"14:00 a 16:00",IF(AND(VALUE(P23)>=VALUE("16:00"),VALUE(P23)<=VALUE("17:59")),"16:00 a 18:00",IF(AND(VALUE(P23)>=VALUE("18:00"),VALUE(P23)<=VALUE("19:59")),"18:00 a 20:00",IF(AND(VALUE(P23)>=VALUE("20:00"),VALUE(P23)<=VALUE("21:59")),"20:00 a 22:00",IF(AND(VALUE(P23)>=VALUE("22:00"),VALUE(P23)<=VALUE("23:59")),"22:00 a 00:00","no corresponde")))))))))))) -> 00:00 a 02:00 | D23: ARGUELLO | E23: CARABAJAL, GRACIELA | F23: 3 | G23: REINAGA, MARTIN | I23: 46737983 | J23: PUERTO MADERO | K23: ROBO/HURTO | N23: SAN NICOLAS 38 | O23: San Nicolas | P23: 0.065972222 | Q23: 0.11111111 | R23: 0.075 | S23: - | T23: - | U23: - | V23: - | W23: SE TOMA CONOCIMIENTO MEDIANTE CARTA SAE QUE UN MASCULINO SUSTRAJO ELEMENTOS DE UNA OBRA EN CONSTRUCCION. PERSONAL POLICIAL DA CON EL MASCULINO QUE SE RETIRA NO HABIENDO TOMADO TEMPERAMENTO PARA EL . | X23: 0 | Y23: 0 | Z23: 0 | AA23: 1D | AB23: U | AC23: CARTA | AF23: CARTA FINALIZADA | AL23: =VLOOKUP(G23,Hoja2!P:Q,2,0) -> 43819657 | AM23: =IF(OR(Y23>0,X23>0),"IMPUTADO","NADA") -> NADA | AN23: =IF(AND(AM23="IMPUTADO",ISBLANK(M23)),"FALTO","NO") -> NO
A24: 45992 | B24: =IF(AND(VALUE(P24)>=VALUE("06:00"),VALUE(P24)<=VALUE("17:59")),"06 A 18","18 A 06") -> 18 A 06 | C24: =IF(AND(VALUE(P24)>=VALUE("00:00"),VALUE(P24)<=VALUE("01:59")),"00:00 a 02:00",IF(AND(VALUE(P24)>=VALUE("02:00"),VALUE(P24)<=VALUE("03:59")),"02:00 a 04:00",IF(AND(VALUE(P24)>=VALUE("04:00"),VALUE(P24)<=VALUE("05:59")),"04:00 a 06:00",IF(AND(VALUE(P24)>=VALUE("06:00"),VALUE(P24)<=VALUE("07:59")),"06:00 a 08:00",IF(AND(VALUE(P24)>=VALUE("08:00"),VALUE(P24)<=VALUE("09:59")),"08:00 a 10:00",IF(AND(VALUE(P24)>=VALUE("10:00"),VALUE(P24)<=VALUE("11:59")),"10:00 a 12:00",IF(AND(VALUE(P24)>=VALUE("12:00"),VALUE(P24)<=VALUE("13:59")),"12:00 a 14:00",IF(AND(VALUE(P24)>=VALUE("14:00"),VALUE(P24)<=VALUE("15:59")),"14:00 a 16:00",IF(AND(VALUE(P24)>=VALUE("16:00"),VALUE(P24)<=VALUE("17:59")),"16:00 a 18:00",IF(AND(VALUE(P24)>=VALUE("18:00"),VALUE(P24)<=VALUE("19:59")),"18:00 a 20:00",IF(AND(VALUE(P24)>=VALUE("20:00"),VALUE(P24)<=VALUE("21:59")),"20:00 a 22:00",IF(AND(VALUE(P24)>=VALUE("22:00"),VALUE(P24)<=VALUE("23:59")),"22:00 a 00:00","no corresponde")))))))))))) -> 04:00 a 06:00 | D24: ARGUELLO | E24: ALCARAZ, ARIEL | F24: 3 | G24: MEZA, ROMINA | H24: 919852 | I24: 46737990 | J24: CHACARITA | K24: INCIDENCIA EN VIA PUBLICA | N24: BALVANERA65 | O24: Balvanera | P24: 0.1875 | Q24: 0.21458333 | R24: 0.19305556 | S24: - | T24: - | U24: - | V24: - | W24: SE TOMA CONOCIMIENTO MEDIANTE CARTA SAE SOBRE DENUNCIANTE QUIEN REFIERE QUE HABRIA UNA PERSONA INCONSCIENTE LUEGO DE UNA PELEA. SE VISUALIZA PERSONAL IDENTIFICANDO A MASCULINO Y DOS FEMENINOS. SE INFORMA SE TRATO DE INCIDENCIA SOLUCIONADA SIN NOVEDAD.- | X24: 0 | Y24: 0 | Z24: 0 | AA24: 3C | AB24: U | AC24: CARTA | AD24: SISEP | AF24: CARTA FINALIZADA | AL24: =VLOOKUP(G24,Hoja2!P:Q,2,0) -> 39712754 | AM24: =IF(OR(Y24>0,X24>0),"IMPUTADO","NADA") -> NADA | AN24: =IF(AND(AM24="IMPUTADO",ISBLANK(M24)),"FALTO","NO") -> NO
A25: 45992 | B25: =IF(AND(VALUE(P25)>=VALUE("06:00"),VALUE(P25)<=VALUE("17:59")),"06 A 18","18 A 06") -> 18 A 06 | C25: =IF(AND(VALUE(P25)>=VALUE("00:00"),VALUE(P25)<=VALUE("01:59")),"00:00 a 02:00",IF(AND(VALUE(P25)>=VALUE("02:00"),VALUE(P25)<=VALUE("03:59")),"02:00 a 04:00",IF(AND(VALUE(P25)>=VALUE("04:00"),VALUE(P25)<=VALUE("05:59")),"04:00 a 06:00",IF(AND(VALUE(P25)>=VALUE("06:00"),VALUE(P25)<=VALUE("07:59")),"06:00 a 08:00",IF(AND(VALUE(P25)>=VALUE("08:00"),VALUE(P25)<=VALUE("09:59")),"08:00 a 10:00",IF(AND(VALUE(P25)>=VALUE("10:00"),VALUE(P25)<=VALUE("11:59")),"10:00 a 12:00",IF(AND(VALUE(P25)>=VALUE("12:00"),VALUE(P25)<=VALUE("13:59")),"12:00 a 14:00",IF(AND(VALUE(P25)>=VALUE("14:00"),VALUE(P25)<=VALUE("15:59")),"14:00 a 16:00",IF(AND(VALUE(P25)>=VALUE("16:00"),VALUE(P25)<=VALUE("17:59")),"16:00 a 18:00",IF(AND(VALUE(P25)>=VALUE("18:00"),VALUE(P25)<=VALUE("19:59")),"18:00 a 20:00",IF(AND(VALUE(P25)>=VALUE("20:00"),VALUE(P25)<=VALUE("21:59")),"20:00 a 22:00",IF(AND(VALUE(P25)>=VALUE("22:00"),VALUE(P25)<=VALUE("23:59")),"22:00 a 00:00","no corresponde")))))))))))) -> 04:00 a 06:00 | D25: ARGUELLO | E25: COLO, NADIA | F25: 3 | G25: REINAGA, MARTIN | H25: 918447 | I25: 46738015 | J25: PUERTO MADERO | K25: IDENTIFICACION DE PERSONAS | N25: RECOLETA96 | O25: Recoleta | P25: 0.19652778 | Q25: 0.23958333 | R25: 0.19930556 | S25: - | T25: - | U25: - | V25: - | W25: SE TOMA CONOCIMIENTO MEDIANTE CARTA SAE POR CUATRO MASCULINOS QUE HABRIAN INGRESADO A UN DEPARTAMENTO MIENTRAS EL DUEÑO DORMIA. LOS CAUSANTES ATARON AL DUEÑO CON PRECINTOS Y SE LLEVARON PERTENENCIAS. SE VERIFICO EL EDIFICIO NO SE LOGRO DAR CON LOS CAUSANTES. | X25: 0 | Y25: 0 | Z25: 0 | AA25: 2A | AB25: U | AC25: CARTA | AF25: CARTA FINALIZADA | AL25: =VLOOKUP(G25,Hoja2!P:Q,2,0) -> 43819657 | AM25: =IF(OR(Y25>0,X25>0),"IMPUTADO","NADA") -> NADA | AN25: =IF(AND(AM25="IMPUTADO",ISBLANK(M25)),"FALTO","NO") -> NO
A26: 45992 | B26: =IF(AND(VALUE(P26)>=VALUE("06:00"),VALUE(P26)<=VALUE("17:59")),"06 A 18","18 A 06") -> 18 A 06 | C26: =IF(AND(VALUE(P26)>=VALUE("00:00"),VALUE(P26)<=VALUE("01:59")),"00:00 a 02:00",IF(AND(VALUE(P26)>=VALUE("02:00"),VALUE(P26)<=VALUE("03:59")),"02:00 a 04:00",IF(AND(VALUE(P26)>=VALUE("04:00"),VALUE(P26)<=VALUE("05:59")),"04:00 a 06:00",IF(AND(VALUE(P26)>=VALUE("06:00"),VALUE(P26)<=VALUE("07:59")),"06:00 a 08:00",IF(AND(VALUE(P26)>=VALUE("08:00"),VALUE(P26)<=VALUE("09:59")),"08:00 a 10:00",IF(AND(VALUE(P26)>=VALUE("10:00"),VALUE(P26)<=VALUE("11:59")),"10:00 a 12:00",IF(AND(VALUE(P26)>=VALUE("12:00"),VALUE(P26)<=VALUE("13:59")),"12:00 a 14:00",IF(AND(VALUE(P26)>=VALUE("14:00"),VALUE(P26)<=VALUE("15:59")),"14:00 a 16:00",IF(AND(VALUE(P26)>=VALUE("16:00"),VALUE(P26)<=VALUE("17:59")),"16:00 a 18:00",IF(AND(VALUE(P26)>=VALUE("18:00"),VALUE(P26)<=VALUE("19:59")),"18:00 a 20:00",IF(AND(VALUE(P26)>=VALUE("20:00"),VALUE(P26)<=VALUE("21:59")),"20:00 a 22:00",IF(AND(VALUE(P26)>=VALUE("22:00"),VALUE(P26)<=VALUE("23:59")),"22:00 a 00:00","no corresponde")))))))))))) -> 04:00 a 06:00 | D26: ARGUELLO | E26: QUINTANA, GILDA | F26: 3 | G26: MONTIEL, JUAN | I26: 46738098 | J26: CHACARITA | K26: COLABORACION | L26: CHOQUE | M26: LESIONES | N26: ALMAGRO05 | O26: Almagro | P26: 0.2 | W26: SE TOMA CONOCIMIENTO MEDIANTE CARTA SAE SOBREDENUNCIANTE QUIEN REFIERE QUE ATROPELLARON A UN OFICIAL DE POLICIA LDE LA CIUDAD. SEVISUALIZA PERSONAL ASISTIENDO A UNA PERSONA TENDIDA SOBRE LA CINTA ASFALTICA. ARRIBA SAME. | X26: 0 | Y26: 1 | Z26: 0 | AA26: 5A | AB26: U | AC26: CARTA | AF26: COLABORACION CON IMPUTADO/S | AL26: =VLOOKUP(G26,Hoja2!P:Q,2,0) -> 46252382 | AM26: =IF(OR(Y26>0,X26>0),"IMPUTADO","NADA") -> IMPUTADO | AN26: =IF(AND(AM26="IMPUTADO",ISBLANK(M26)),"FALTO","NO") -> NO
A27: 45992 | B27: =IF(AND(VALUE(P27)>=VALUE("06:00"),VALUE(P27)<=VALUE("17:59")),"06 A 18","18 A 06") -> 06 A 18 | C27: =IF(AND(VALUE(P27)>=VALUE("00:00"),VALUE(P27)<=VALUE("01:59")),"00:00 a 02:00",IF(AND(VALUE(P27)>=VALUE("02:00"),VALUE(P27)<=VALUE("03:59")),"02:00 a 04:00",IF(AND(VALUE(P27)>=VALUE("04:00"),VALUE(P27)<=VALUE("05:59")),"04:00 a 06:00",IF(AND(VALUE(P27)>=VALUE("06:00"),VALUE(P27)<=VALUE("07:59")),"06:00 a 08:00",IF(AND(VALUE(P27)>=VALUE("08:00"),VALUE(P27)<=VALUE("09:59")),"08:00 a 10:00",IF(AND(VALUE(P27)>=VALUE("10:00"),VALUE(P27)<=VALUE("11:59")),"10:00 a 12:00",IF(AND(VALUE(P27)>=VALUE("12:00"),VALUE(P27)<=VALUE("13:59")),"12:00 a 14:00",IF(AND(VALUE(P27)>=VALUE("14:00"),VALUE(P27)<=VALUE("15:59")),"14:00 a 16:00",IF(AND(VALUE(P27)>=VALUE("16:00"),VALUE(P27)<=VALUE("17:59")),"16:00 a 18:00",IF(AND(VALUE(P27)>=VALUE("18:00"),VALUE(P27)<=VALUE("19:59")),"18:00 a 20:00",IF(AND(VALUE(P27)>=VALUE("20:00"),VALUE(P27)<=VALUE("21:59")),"20:00 a 22:00",IF(AND(VALUE(P27)>=VALUE("22:00"),VALUE(P27)<=VALUE("23:59")),"22:00 a 00:00","no corresponde")))))))))))) -> 06:00 a 08:00 | D27: MARTINEZ. R | E27: MEZA, GASTON | F27: 1 | G27: ROJAS MELANIE | H27: 918234 | I27: 46738272 | J27: CMU 9 DE JULIO | K27: INCIDENCIA EN VIA PUBLICA | M27: PEDIDO DE CAPTURA | N27: CONSTITUCION 23 | O27: Constitucion | P27: 0.26388889 | Q27: 0.28333333 | R27: 0.26875 | V27: - | W27: SE VISUALIZA POR CAMARA CONSTITUCION 23 UNA INCIDENCIA EN EL LUGAR. SE AVISO A COMANDO. ARRIBA PERSONAL POLICIAL. 901C INF SE REALIZO CONSULTA CON EL JUZGADO NCC NRO 58 AC DR GRUÑAR SECRETARIA NRO 64 AC DR JUAN ZIELLI QUIEN DISPUSO DETENCION DE LA FEMENINO QUIEN POSEIA UN PEDIDO VIGENTE, TRASLADO A CV1C.- | X27: 0 | Y27: 1 | Z27: 0 | AA27: 1C | AB27: U | AC27: MONITOREO | AE27: 1 DETENIDO | AF27: FINALIZA CON IMPUTADO/S | AL27: =VLOOKUP(G27,Hoja2!P:Q,2,0) -> 40097155 | AM27: =IF(OR(Y27>0,X27>0),"IMPUTADO","NADA") -> IMPUTADO | AN27: =IF(AND(AM27="IMPUTADO",ISBLANK(M27)),"FALTO","NO") -> NO
A28: 45992 | B28: =IF(AND(VALUE(P28)>=VALUE("06:00"),VALUE(P28)<=VALUE("17:59")),"06 A 18","18 A 06") -> 06 A 18 | C28: =IF(AND(VALUE(P28)>=VALUE("00:00"),VALUE(P28)<=VALUE("01:59")),"00:00 a 02:00",IF(AND(VALUE(P28)>=VALUE("02:00"),VALUE(P28)<=VALUE("03:59")),"02:00 a 04:00",IF(AND(VALUE(P28)>=VALUE("04:00"),VALUE(P28)<=VALUE("05:59")),"04:00 a 06:00",IF(AND(VALUE(P28)>=VALUE("06:00"),VALUE(P28)<=VALUE("07:59")),"06:00 a 08:00",IF(AND(VALUE(P28)>=VALUE("08:00"),VALUE(P28)<=VALUE("09:59")),"08:00 a 10:00",IF(AND(VALUE(P28)>=VALUE("10:00"),VALUE(P28)<=VALUE("11:59")),"10:00 a 12:00",IF(AND(VALUE(P28)>=VALUE("12:00"),VALUE(P28)<=VALUE("13:59")),"12:00 a 14:00",IF(AND(VALUE(P28)>=VALUE("14:00"),VALUE(P28)<=VALUE("15:59")),"14:00 a 16:00",IF(AND(VALUE(P28)>=VALUE("16:00"),VALUE(P28)<=VALUE("17:59")),"16:00 a 18:00",IF(AND(VALUE(P28)>=VALUE("18:00"),VALUE(P28)<=VALUE("19:59")),"18:00 a 20:00",IF(AND(VALUE(P28)>=VALUE("20:00"),VALUE(P28)<=VALUE("21:59")),"20:00 a 22:00",IF(AND(VALUE(P28)>=VALUE("22:00"),VALUE(P28)<=VALUE("23:59")),"22:00 a 00:00","no corresponde")))))))))))) -> 06:00 a 08:00 | D28: MARTINEZ. R | E28: MEZA, GASTON | F28: 1 | G28: KRAKOVSKY, FLORENCIA | H28: 918510 | I28: 46738334 | J28: CMU 9 DE JULIO | K28: COLABORACION | L28: CHOQUE | N28: SAN NICOLAS 03 | O28: San Nicolas | P28: 0.28125 | Q28: 0.30208333 | R28: 0.28125 | V28: - | W28: SE TOMA CONOCIMIENTO MEDIANTE CARTA SAE HT V/P SOLCITA SAME PARA MASCULINO ATROPELLADO . SE POSEE CAMARA SAN NICOLAS 03 SE VISUALIZA A UN MASCULINO TENDIDO EN EL SUELO SIENDO ASISTIDO POR PERSONALN POLICIAL. SE AMPLIA LINEA DE TIEMPO POR CAMARA SAN NICOLAS 03 CAM 02_ SIENDO LAS 06:32 HS SE VISUALIZA A UN MASCULINO CRUZAR POR EL MEDION LA AVENIDA CON LOS VEHICULOS CIRCULANDO FUERA DE LA SENDA PEATONAL EN FORMA IMPRUDENTE MOMENTO EN EL CUAL ES ENVESTIDO POR UN VEHICULO PARTICULAR COLOR OSCURO. SE AMPLIA M 601 INF ENTREVISTA AL MASC EN SIT DE CALLE DAMNIFICADO QUIEN REF SE ENCONTRABA CRUZANDO LA CALLE DE MANERA IMPRUDENTE Y MASC LE HABRAI PISADO EL PIE EL MISMO AL ARRIBO DEL MOVIL SE HABRIA RETIRADO Y PARA CON LA PARTE DAMNIFICADDA QUIEN REF NO INSTA A LA ACCION PENAL ES ASISTIDA POR PERSONAL MEDICO MEDIANTE TELEMEDICINA A SU VEZ SE NEGO A LA ASISTENCIA EL MISMO SE RETIRA POR SUS PROPIOS MEDIOS EN BUENAS CONDICIONES, A SU VEZ SE EVACUA CONSULTA A LA UFLA ESTE A LA VOZ DEL DR DEBRACHI QUIEN INDICA SE DEJE CONSTANCIA EN EL PARTE | X28: 0 | Y28: 0 | Z28: 0 | AA28: 1D | AB28: U | AC28: CARTA | AF28: CARTA FINALIZADA | AL28: =VLOOKUP(G28,Hoja2!P:Q,2,0) -> 41290026 | AM28: =IF(OR(Y28>0,X28>0),"IMPUTADO","NADA") -> NADA | AN28: =IF(AND(AM28="IMPUTADO",ISBLANK(M28)),"FALTO","NO") -> NO
A29: 45992 | B29: =IF(AND(VALUE(P29)>=VALUE("06:00"),VALUE(P29)<=VALUE("17:59")),"06 A 18","18 A 06") -> 06 A 18 | C29: =IF(AND(VALUE(P29)>=VALUE("00:00"),VALUE(P29)<=VALUE("01:59")),"00:00 a 02:00",IF(AND(VALUE(P29)>=VALUE("02:00"),VALUE(P29)<=VALUE("03:59")),"02:00 a 04:00",IF(AND(VALUE(P29)>=VALUE("04:00"),VALUE(P29)<=VALUE("05:59")),"04:00 a 06:00",IF(AND(VALUE(P29)>=VALUE("06:00"),VALUE(P29)<=VALUE("07:59")),"06:00 a 08:00",IF(AND(VALUE(P29)>=VALUE("08:00"),VALUE(P29)<=VALUE("09:59")),"08:00 a 10:00",IF(AND(VALUE(P29)>=VALUE("10:00"),VALUE(P29)<=VALUE("11:59")),"10:00 a 12:00",IF(AND(VALUE(P29)>=VALUE("12:00"),VALUE(P29)<=VALUE("13:59")),"12:00 a 14:00",IF(AND(VALUE(P29)>=VALUE("14:00"),VALUE(P29)<=VALUE("15:59")),"14:00 a 16:00",IF(AND(VALUE(P29)>=VALUE("16:00"),VALUE(P29)<=VALUE("17:59")),"16:00 a 18:00",IF(AND(VALUE(P29)>=VALUE("18:00"),VALUE(P29)<=VALUE("19:59")),"18:00 a 20:00",IF(AND(VALUE(P29)>=VALUE("20:00"),VALUE(P29)<=VALUE("21:59")),"20:00 a 22:00",IF(AND(VALUE(P29)>=VALUE("22:00"),VALUE(P29)<=VALUE("23:59")),"22:00 a 00:00","no corresponde")))))))))))) -> 06:00 a 08:00 | D29: MARTINEZ. R | E29: ARREGUI, FERNANDO | F29: 1 | G29: CARRIZO RODRIGO | H29: 918285 | I29: 46738371 | J29: CHACARITA | K29: COLABORACION | L29: INCIDENCIA | N29: CABALLITO 04 | O29: Caballito | P29: 0.29861111 | Q29: 0.30972222 | R29: 0.29861111 | S29: - | T29: - | U29: - | V29: - | W29: SE TOMA CONOCIMIENTO MEDIANTE CARTA SAE FEMENINO REFIERE INCIDENCIA CON UN MASCULINO. AGUARDA JANA NAHIR. 4º A..- CMU INF, SE POSEE CAMARA CABALLITO11 SE VISUALIZA PERSONAL POLICIAL EN EL LUGAR.- 606 INF SE ENTRVISTA CON LA SEÑORA QUIEN LE BRIDA EL ACCESO - DA CON LA PROPIETARIA DEL 4A - RECORREN EL EDIFICIO PANAMA NORMAL NEGATIVO PERSONAS EXTRAÑAS | X29: 0 | Y29: 0 | Z29: 0 | AA29: 6A | AB29: U | AC29: CARTA | AF29: CARTA FINALIZADA | AL29: =VLOOKUP(G29,Hoja2!P:Q,2,0) -> 43444086 | AM29: =IF(OR(Y29>0,X29>0),"IMPUTADO","NADA") -> NADA | AN29: =IF(AND(AM29="IMPUTADO",ISBLANK(M29)),"FALTO","NO") -> NO
