Workbook

Sheet NOVIEMBRE 2025
A1: OPERADOR | B1: GAP | C1: SAE | D1: APLICA | E1: COLABORADORES 1 | F1: COLABORADORES 2 | G1: COLABORADORES 3 | H1: COLABORADORES 4 | I1: COLABORADORES 5 | J1: COLABORADORES 6 | K1: ORIGEN
A2: MENDOZ, LUCIANO | B2: 748108 | C2: 46141590 | D2: SI | E2: LASTRA, PERLA | J2: ANGLADA, ANA | K2: =VLOOKUP(C2,MAESTRO!A:B,2,0) -> #N/A
A3: RODRIGUEZ, SOFIA | B3: 733936 | C3: 46103310 | D3: SI | E3: CARDOZO, ROMINA | J3: ARGAÑARAZ BRIAN | K3: =VLOOKUP(C3,MAESTRO!A:B,2,0) -> #N/A
A4: RODRIGUEZ, SOFIA | B4: 740473 | C4: 46105164 | D4: SI | E4: ROBLES, LARA VALENTINA | J4: ARGAÑARAZ BRIAN | K4: =VLOOKUP(C4,MAESTRO!A:B,2,0) -> #N/A
A5: RODRIGUEZ, SOFIA | B5: 750093 | C5: 46154594 | D5: SI | E5: CHARON, FLORENCIA | J5: ARGAÑARAZ BRIAN | K5: =VLOOKUP(C5,MAESTRO!A:B,2,0) -> #N/A
A6: PALACIOS, SOFIA | B6: 720729 | C6: 46059014 | D6: SI | J6: AVILA SAMIRA | K6: =VLOOKUP(C6,MAESTRO!A:B,2,0) -> #N/A
A7: SOLDANI, CLARA | B7: 734049 | C7: 46104011 | D7: SI | E7: SABELLA, ROSA MARIA | J7: AVILA SAMIRA | K7: =VLOOKUP(C7,MAESTRO!A:B,2,0) -> #N/A
A8: RODRIGUEZ, SOFIA | B8: 741329 | C8: 46105922 | D8: SI | E8: PAZ, AGUSTIN DANIEL | J8: AVILA SAMIRA | K8: =VLOOKUP(C8,MAESTRO!A:B,2,0) -> #N/A
A9: RODRIGUEZ, SOFIA | B9: 740479 | C9: 46106883 | D9: SI | E9: CABRAL, NATALIA | J9: AVILA SAMIRA | K9: =VLOOKUP(C9,MAESTRO!A:B,2,0) -> #N/A
A10: BERGARA, ANDREA | B10: 684153 | C10: 45964286 | D10: SI | E10: MEZA, ROMINA | J10: BARZOLA, DYLAN | K10: =VLOOKUP(C10,MAESTRO!A:B,2,0) -> #N/A
A11: GAVELLO, ANABELA | B11: 701659 | C11: 46009889 | D11: SI | F11: MANRIQUE, GASTÓN | G11: ALONSO, JORGE ANTONIO | J11: BARZOLA, DYLAN | K11: =VLOOKUP(C11,MAESTRO!A:B,2,0) -> #N/A
A12: CUELLAR, CAMILA | B12: 719011 | C12: 46054986 | D12: SI | E12: MEZA, ROMINA | J12: BARZOLA, DYLAN | K12: =VLOOKUP(C12,MAESTRO!A:B,2,0) -> #N/A
A13: DONADON, NICOLAS | B13: 728866 | C13: 46077824 | D13: SI | J13: BARZOLA, DYLAN | K13: =VLOOKUP(C13,MAESTRO!A:B,2,0) -> #N/A
A14: VEGA BRISA | B14: 728786 | C14: 46077815 | D14: SI | E14: BENDITTI, JULIETA | J14: BARZOLA, DYLAN | K14: =VLOOKUP(C14,MAESTRO!A:B,2,0) -> #N/A
A15: RIGONI, VALENTINA | B15: 729765 | C15: 46078683 | D15: SI | J15: BARZOLA, DYLAN | K15: =VLOOKUP(C15,MAESTRO!A:B,2,0) -> #N/A
A16: ORREGO, PAMELA | B16: 729042 | C16: 46078842 | D16: SI | J16: BARZOLA, DYLAN | K16: =VLOOKUP(C16,MAESTRO!A:B,2,0) -> #N/A
A17: CUELLAR, CAMILA | B17: 728959 | C17: 46078503 | D17: SI | J17: BARZOLA, DYLAN | K17: =VLOOKUP(C17,MAESTRO!A:B,2,0) -> #N/A
A18: RIGONI, VALENTINA | B18: 742823 | C18: 46126059 | D18: SI | J18: BARZOLA, DYLAN | K18: =VLOOKUP(C18,MAESTRO!A:B,2,0) -> #N/A
A19: ISLEÑO, LUCAS | B19: 755213 | C19: 46170712 | D19: SI | J19: BARZOLA, DYLAN | K19: =VLOOKUP(C19,MAESTRO!A:B,2,0) -> #N/A
A20: ROJAS, PRISCILA | B20: 732566 | C20: 46095365 | D20: SI | E20: GARCIA, LUDMILA | J20: CARABALLO, LUCAS | K20: =VLOOKUP(C20,MAESTRO!A:B,2,0) -> #N/A
A21: LENCINA, CRISTINA | B21: 741685 | C21: 46120933 | D21: SI | E21: ACOSTA, DAMARIS AYLEN | J21: CASERES NICOLE | K21: =VLOOKUP(C21,MAESTRO!A:B,2,0) -> #N/A
A22: RODRIGUEZ, SOFIA | B22: 758589 | C22: 46182552 | D22: SI | E22: FARIAS, NAHUEL | J22: CASERES NICOLE | K22: =VLOOKUP(C22,MAESTRO!A:B,2,0) -> #N/A
A23: MACIAS, SANTIAGO | B23: 694964 | C23: 45994249 | D23: SI | J23: DAUMAS, VICTORIA SOL | K23: =VLOOKUP(C23,MAESTRO!A:B,2,0) -> #N/A
A24: MEZA, ROMINA | B24: 695181 | C24: 45995861 | D24: SI | J24: DAUMAS, VICTORIA SOL | K24: =VLOOKUP(C24,MAESTRO!A:B,2,0) -> CARTA
A25: GONZALEZ, EZEQUIEL WALTER | B25: 704899 | C25: 46017409 | D25: SI | E25: SANDOVAL, JEREMIAS | J25: DAUMAS, VICTORIA SOL | K25: =VLOOKUP(C25,MAESTRO!A:B,2,0) -> #N/A
A26: MONTIEL, JUAN RAMON | B26: 704892 | C26: 46017345 | D26: SI | E26: INFANTE, JONATHAN | F26: ALONSO, JORGE ANTONIO | J26: DAUMAS, VICTORIA SOL | K26: =VLOOKUP(C26,MAESTRO!A:B,2,0) -> #N/A
A27: MENDOZ, LUCIANO | B27: 698482 | C27: 46002852 | D27: SI | F27: SANDOVAL, JEREMIAS | G27: CACERES MATIAS NAHUEL | J27: FERRANDO, MARTINA | K27: =VLOOKUP(C27,MAESTRO!A:B,2,0) -> #N/A
A28: DOMINGUEZ, JAMAL | B28: 718676 | C28: 46052962 | D28: SI | J28: GAMBINO, DANIEL | K28: =VLOOKUP(C28,MAESTRO!A:B,2,0) -> #N/A
A29: ORREGO, PAMELA | B29: 728782 | C29: 46077103 | D29: SI | J29: GAMBINO, DANIEL | K29: =VLOOKUP(C29,MAESTRO!A:B,2,0) -> #N/A
A30: MORALES, EZEQUIEL DARIO | B30: 728936 | C30: 46076870 | D30: SI | J30: GAMBINO, DANIEL | K30: =VLOOKUP(C30,MAESTRO!A:B,2,0) -> #N/A
A31: GONZALEZ MAIDANA, KAMILA RAQUEL | B31: 711358 | C31: 46033315 | D31: SI | J31: LARREA, YESICA | K31: =VLOOKUP(C31,MAESTRO!A:B,2,0) -> #N/A
A32: BERNAL, LAILA | B32: 711360 | C32: 46033240 | D32: SI | J32: LARREA, YESICA | K32: =VLOOKUP(C32,MAESTRO!A:B,2,0) -> #N/A
A33: GAROSO, ANA LAURA | B33: 690306 | C33: 45978189 | D33: SI | E33: CABRAL, NATALIA | J33: LEGUIZAMÓN, KARINA | K33: =VLOOKUP(C33,MAESTRO!A:B,2,0) -> #N/A
A34: BOMONE, NICOLAS IVAN | B34: 748066 | C34: 46141806 | D34: SI | J34: LEGUIZAMÓN, KARINA | K34: =VLOOKUP(C34,MAESTRO!A:B,2,0) -> #N/A
A35: GUTIERREZ, FACUNDO | B35: 764273 | C35: 46210093 | D35: SI | E35: PONCE DE LEON, CINDY MARIBEL | J35: LEGUIZAMÓN, KARINA | K35: =VLOOKUP(C35,MAESTRO!A:B,2,0) -> #N/A
A36: ALONSO, JORGE ANTONIO | B36: 684133 | C36: 45964035 | D36: SI | J36: LOPEZ, CAMILA ANDREA | K36: =VLOOKUP(C36,MAESTRO!A:B,2,0) -> #N/A
A37: BERGARA, ANDREA | B37: 701735 | C37: 46010375 | D37: SI | J37: LOPEZ, CAMILA ANDREA | K37: =VLOOKUP(C37,MAESTRO!A:B,2,0) -> #N/A
A38: SCHIRRIPA, ESTEBAN | B38: 718967 | C38: 46054880 | D38: SI | J38: LOPEZ, CAMILA ANDREA | K38: =VLOOKUP(C38,MAESTRO!A:B,2,0) -> #N/A
A39: FEDELLE, SANDRA ANALÍA | B39: 728855 | C39: 46077269 | D39: SI | J39: LOPEZ, CAMILA ANDREA | K39: =VLOOKUP(C39,MAESTRO!A:B,2,0) -> #N/A
A40: ZAMUDIO, ALEJANDRO | B40: 728604 | C40: 46076774 | D40: SI | J40: LOPEZ, CAMILA ANDREA | K40: =VLOOKUP(C40,MAESTRO!A:B,2,0) -> #N/A
...

Sheet MAESTRO
A1: SAE | B1: ORIGEN
A2: 45995186 | B2: CARTA
A3: 45995282 | B3: CARTA
A4: 45995377 | B4: CARTA
A5: 45995353 | B5: CARTA
A6: 45995467 | B6: CARTA
A7: 45995550 | B7: CARTA
A8: 45995586 | B8: CARTA
A9: 45995649 | B9: CARTA
A10: 45995648 | B10: CARTA
A11: 45995680 | B11: CARTA
A12: 45995710 | B12: CARTA
A13: 45995749 | B13: CARTA
... A90: 46000893 | B90: CARTA
